Workbook
Name _Box1: #REF!
Name _Box10: #REF!
Name _Box11: #REF!
Name _Box12: #REF!
Name _Box13: #REF!
Name _Box2: #REF!
Name _Box3: #REF!
Name _Box4: #REF!
Name _Box5: #REF!
Name _Box6: #REF!
Name _Box7: #REF!
Name _Box8: #REF!
Name _Box9: #REF!
Name _dep01: [2]Sheet1!$M$126
Name _dep93: [2]Sheet1!$E$166
Name _dep94: [2]Sheet1!$F$166
Name _dep95: [2]Sheet1!$G$166
Name _dep96: [2]Sheet1!$H$166
Name _dep97: [2]Sheet1!$I$166
Name _dep98: [2]Sheet1!$J$166
Name _dep99: [2]Sheet1!$K$126
Name _dps01: [2]Sheet1!$M$14
Name _dps93: [2]Sheet1!$E$14
Name _dps94: [2]Sheet1!$F$14
Name _dps95: [2]Sheet1!$G$14
Name _dps96: [2]Sheet1!$H$14
Name _dps97: [2]Sheet1!$I$14
Name _dps98: [2]Sheet1!$J$14
Name _dps99: [2]Sheet1!$K$14
Name _dpu99: #REF!
Name _gcf99: #REF!
Name _int01: [2]Sheet1!$M$44
Name _int93: [2]Sheet1!$E$44
Name _int94: [2]Sheet1!$F$44
Name _int95: [2]Sheet1!$G$44
Name _int96: [2]Sheet1!$H$44
Name _int97: [2]Sheet1!$I$44
Name _int98: [2]Sheet1!$J$44
Name _int99: [2]Sheet1!$K$44
Name _nde01: [2]Sheet1!$M$150
Name _nde93: [2]Sheet1!$E$150
Name _nde94: [2]Sheet1!$F$150
Name _nde95: [2]Sheet1!$G$150
Name _nde96: [2]Sheet1!$H$150
Name _nde97: [2]Sheet1!$I$150
Name _nde98: [2]Sheet1!$J$150
Name _nde99: [2]Sheet1!$K$150
Name _nta01: [2]Sheet1!$M$16
Name _nta93: [2]Sheet1!$E$16
Name _nta94: [2]Sheet1!$F$16
Name _nta95: [2]Sheet1!$G$16
Name _nta96: [2]Sheet1!$H$16
Name _nta97: [2]Sheet1!$I$16
Name _nta98: [2]Sheet1!$J$16
Name _nta99: [2]Sheet1!$K$16
Name _roa01: [2]Sheet1!$M$155
Name _roa93: [2]Sheet1!$E$155
Name _roa94: [2]Sheet1!$F$155
Name _roa95: [2]Sheet1!$G$155
Name _roa96: [2]Sheet1!$H$155

Sheet __FDSCACHE__
B1: This sheet contains FactSet XML data for use with this workbook's =FDS codes. Modifying the worksheet's contents may damage the workbook's =FDS functionality.

Sheet IS
A1: Tutor Perini | Y1: =+Y79 -> 0 | AX1: **NOTE - I DID NOT CREATE THIS MODEL, IT WAS PROVIDED AS PART OF A MODELING TEST ON AN INTERVIEW. I HAVE BEEN UPDATING IT QUARTERLY SINCE Q12018
A2: Income Statement (US$ Millions) | F2: 40268 | G2: =EOMONTH(F2,3) -> 40359 | H2: =EOMONTH(G2,3) -> 40451 | I2: =EOMONTH(H2,3) -> 40543 | K2: =+EOMONTH(F2,12) -> 40633 | L2: =+EOMONTH(G2,12) -> 40724 | M2: =+EOMONTH(H2,12) -> 40816 | N2: =+EOMONTH(I2,12) -> 40908 | P2: =+EOMONTH(K2,12) -> 40999 | Q2: =+EOMONTH(L2,12) -> 41090 | R2: =+EOMONTH(M2,12) -> 41182 | S2: =+EOMONTH(N2,12) -> 41274 | U2: =+EOMONTH(P2,12) -> 41364 | V2: =+EOMONTH(Q2,12) -> 41455 | W2: =+EOMONTH(R2,12) -> 41547 | X2: =+EOMONTH(S2,12) -> 41639 | Y2: =+Y19-T19 -> 425.633 | Z2: =+EOMONTH(U2,12) -> 41729 | AA2: =+EOMONTH(V2,12) -> 41820 | AB2: =+EOMONTH(W2,12) -> 41912 | AC2: =+EOMONTH(X2,12) -> 42004 | AD2: =#REF! -> #REF! | AE2: =+EOMONTH(Z2,12) -> 42094 | AF2: =+EOMONTH(AA2,12) -> 42185 | AG2: =+EOMONTH(X2,12) -> 42004 | AH2: =+EOMONTH(AC2,12) -> 42369 | AJ2: =+EOMONTH(AE2,12) -> 42460 | AK2: =+EOMONTH(AF2,12) -> 42551 | AL2: =+EOMONTH(AG2,12) -> 42369 | AM2: =+EOMONTH(AH2,12) -> 42735 | AO2: =+EOMONTH(AJ2,12) -> 42825 | AP2: =+EOMONTH(AK2,12) -> 42916 | AQ2: =+EOMONTH(AL2,12) -> 42735 | AR2: =+EOMONTH(AM2,12) -> 43100 | AS2: =#REF! -> #REF! | AT2: =+EOMONTH(AO2,12) -> 43190 | AU2: =+EOMONTH(AP2,12) -> 43281 | AV2: =+EOMONTH(AQ2,12) -> 43100 | AW2: =+EOMONTH(AR2,12) -> 43465 | AX2: =#REF! -> #REF! | AY2: =+EOMONTH(AT2,12) -> 43555 | AZ2: =+EOMONTH(AU2,12) -> 43646 | BA2: =+EOMONTH(AV2,12) -> 43465 | BB2: =+EOMONTH(AW2,12) -> 43830 | BD2: =+EOMONTH(AY2,12) -> 43921 | BE2: =+EOMONTH(AZ2,12) -> 44012 | BF2: =+EOMONTH(BA2,12) -> 43830 | BG2: =+EOMONTH(BB2,12) -> 44196 | BI2: =+EOMONTH(BD2,12) -> 44286 | BJ2: =+EOMONTH(BE2,12) -> 44377 | BK2: =+EOMONTH(BF2,12) -> 44196 | BL2: =+EOMONTH(BG2,12) -> 44561 | BN2: =+EOMONTH(BI2,12) -> 44651 | BO2: =+EOMONTH(BJ2,12) -> 44742 | BP2: =+EOMONTH(BK2,12) -> 44561 | BQ2: =+EOMONTH(BL2,12) -> 44926
A3: TPC | F3: 2010 | J3: =+F3 -> 2010 | K3: 2011 | O3: =+K3 -> 2011 | P3: 2012 | T3: =+P3 -> 2012 | U3: 2013 | Y3: =+U3 -> 2013 | Z3: 2014 | AD3: =+Z3 -> 2014 | AE3: 2015 | AI3: =+AE3 -> 2015 | AJ3: 2016 | AN3: =+AJ3 -> 2016 | AO3: 2017 | AS3: =+AO3 -> 2017 | AT3: 2018 | AX3: =+AT3 -> 2018 | AY3: 2019 | BC3: =+AY3 -> 2019 | BD3: 2020E | BH3: =+BD3 -> 2020E | BI3: 2021E | BM3: =+BI3 -> 2021E | BN3: 2022E | BR3: =+BN3 -> 2022E
A4: Fiscal YE December | F4: 1Q | G4: 2Q | H4: 3Q | I4: 4Q | J4: Year | K4: 1Q | L4: 2Q | M4: 3Q | N4: 4Q | O4: Year | P4: 1Q | Q4: 2Q | R4: 3Q | S4: 4Q | T4: Year | U4: 1Q | V4: 2QE | W4: 3QE | X4: 4QE | Y4: Year | Z4: 1Q | AA4: 2Q | AB4: 3Q | AC4: 4Q | AD4: Year | AE4: 1Q | AF4: 2Q | AG4: 3Q | AH4: 4Q | AI4: Year | AJ4: 1Q | AK4: 2Q | AL4: 3Q | AM4: 4Q | AN4: Year | AO4: 1Q | AP4: 2Q | AQ4: 3Q | AR4: 4Q | AS4: Year | AT4: 1Q | AU4: 2Q | AV4: 3Q | AW4: 4Q | AX4: Year | AY4: 1Q | AZ4: 2Q | BA4: 3Q | BB4: 4QE | BC4: Year | BD4: 1QE | BE4: 2QE | BF4: 3QE | BG4: 4QE | BH4: Year | BI4: 1QE | BJ4: 2QE | BK4: 3QE | BL4: 4QE | BM4: Year | BN4: 1QE | BO4: 2QE | BP4: 3QE | BQ4: 4QE | BR4: Year
A5: Revenues by Segment
A6: Building | F6: 686.284 | G6: 663.157 | H6: 520.671 | I6: =J6-H6-G6-F6 -> 456.868 | J6: 2326.98 | K6: 440.429 | L6: 599.977 | M6: 567.676 | N6: =O6-M6-L6-K6 -> 343.948 | O6: 1952.03 | P6: 343.039 | Q6: 331.924 | R6: 391.531 | S6: =T6-R6-Q6-P6 -> 412.014 | T6: 1478.508 | U6: 425.114 | V6: 422.366 | W6: 352.013 | X6: =Y6-W6-V6-U6 -> 337.734 | Y6: 1537.227 | Z6: 311.315 | AA6: 390.353 | AB6: 420.404 | AC6: 436.359 | AD6: =SUM(Z6:AC6) -> 1558.431 | AE6: 416.063 | AF6: 472.247 | AG6: 506.259 | AH6: 505.924 | AI6: =+SUM(AE6:AH6) -> 1900.493 | AJ6: 487.994 | AK6: 523.521 | AL6: 560.795 | AM6: 551.801 | AN6: =+SUM(AJ6:AM6) -> 2124.111 | AO6: 515.251 | AP6: 508.769 | AQ6: 500.42 | AR6: 462.501 | AS6: =+SUM(AO6:AR6) -> 1986.941 | AT6: 490.617 | AU6: 447.975 | AV6: 457.304 | AW6: 471.006 | AX6: =+SUM(AT6:AW6) -> 1866.902 | AY6: 436.243 | AZ6: 433.559 | BA6: 421.241 | BB6: =AX6*BB81 -> 517.08347 | BC6: =Backlog!W35 -> 1822.4582 | BD6: =$BC6*BD81 -> 388.89198 | BE6: =$BC6*BE81 -> 457.09044 | BF6: =$BC6*BF81 -> 466.79635 | BG6: =$BC6*BG81 -> 509.67947 | BH6: =Backlog!X35 -> 1988.2877 | BI6: =$BC6*BI81 -> 381.44193 | BJ6: =$BC6*BJ81 -> 459.06958 | BK6: =$BC6*BK81 -> 463.20683 | BL6: =$BC6*BL81 -> 518.73991 | BM6: =Backlog!Y35 -> 2040.4516 | BN6: =$BC6*BN81 -> 358.65303 | BO6: =$BC6*BO81 -> 457.17395 | BP6: =$BC6*BP81 -> 464.25997 | BQ6: =$BC6*BQ81 -> 542.37131 | BR6: =Backlog!Z35 -> 2053.8202
A7: Civil | F7: 124.66 | G7: 197.431 | H7: 169.88 | I7: =J7-H7-G7-F7 -> 175.733 | J7: 667.704 | K7: 128.825 | L7: 141.442 | M7: 281.355 | N7: =O7-M7-L7-K7 -> 345.274 | O7: 896.896 | P7: 250.589 | Q7: 327.072 | R7: 350.542 | S7: =T7-R7-Q7-P7 -> 362.407 | T7: 1290.61 | U7: 283.975 | V7: 332.223 | W7: 379.765 | X7: =Y7-W7-V7-U7 -> 427.809 | Y7: 1423.772 | Z7: 376.392 | AA7: 398.123 | AB7: 496.142 | AC7: 459.811 | AD7: =SUM(Z7:AC7) -> 1730.468 | AE7: 392.876 | AF7: 573.36 | AG7: 604.317 | AH7: 434.64 | AI7: =+SUM(AE7:AH7) -> 2005.193 | AJ7: 367.501 | AK7: 465.707 | AL7: 506.1 | AM7: 452.327 | AN7: =+SUM(AJ7:AM7) -> 1791.635 | AO7: 338.108 | AP7: 538.552 | AQ7: 458.487 | AR7: 492.314 | AS7: =+SUM(AO7:AR7) -> 1827.461 | AT7: 325.4 | AU7: 461.614 | AV7: 479.581 | AW7: 543.637 | AX7: =+SUM(AT7:AW7) -> 1810.232 | AY7: 383.622 | AZ7: 541.117 | BA7: 591.884 | BB7: =AX7*BB82 -> 469.37366 | BC7: =Backlog!W33 -> 3021.1949 | BD7: =$BC7*BD82 -> 546.95096 | BE7: =$BC7*BE82 -> 830.33826 | BF7: =$BC7*BF82 -> 828.41794 | BG7: =$BC7*BG82 -> 815.48769 | BH7: =Backlog!X33 -> 3555.3498 | BI7: =$BC7*BI82 -> 528.76148 | BJ7: =$BC7*BJ82 -> 841.59494 | BK7: =$BC7*BK82 -> 822.16609 | BL7: =$BC7*BL82 -> 828.67233 | BM7: =Backlog!Y33 -> 4586.0774 | BN7: =$BC7*BN82 -> 521.21014 | BO7: =$BC7*BO82 -> 829.40746 | BP7: =$BC7*BP82 -> 838.21266 | BQ7: =$BC7*BQ82 -> 832.36459 | BR7: =Backlog!Z33 -> 5582.3667
A8: Specialty Contractors | M8: 335.921 | N8: =O8-M8-L8-K8 -> 466.614 | O8: 802.535 | P8: 267.736 | Q8: 275.902 | R8: 315.27 | S8: =T8-R8-Q8-P8 -> 324.61 | T8: 1183.518 | U8: 301.877 | V8: 284.036 | W8: 287.633 | X8: =Y8-W8-V8-U8 -> 309.298 | Y8: 1182.844 | Z8: 292.145 | AA8: 321.959 | AB8: 355.932 | AC8: 331.292 | AD8: =SUM(Z8:AC8) -> 1301.328 | AE8: 293.017 | AF8: 326.798 | AG8: 325.365 | AH8: 282.849 | AI8: =+SUM(AE8:AH8) -> 1228.029 | AJ8: 281.773 | AK8: 318.902 | AL8: 331.613 | AM8: 301.983 | AN8: =+SUM(AJ8:AM8) -> 1234.271 | AO8: 315.696 | AP8: 281.857 | AQ8: 310.137 | AR8: 306.018 | AS8: =+SUM(AO8:AR8) -> 1213.708 | AT8: 274.801 | AU8: 270.633 | AV8: 236.157 | AW8: 225.279 | AX8: =+SUM(AT8:AW8) -> 1006.87 | AY8: 191.527 | AZ8: 223.299 | BA8: 249.453 | BB8: =AX7*BB83 -> 481.26714 | BC8: =Backlog!W38 -> 1232.3809 | BD8: =$BC8*BD83 -> 264.23834 | BE8: =$BC8*BE83 -> 306.11383 | BF8: =$BC8*BF83 -> 323.44155 | BG8: =$BC8*BG83 -> 338.58717 | BH8: =Backlog!X38 -> 1263.4234 | BI8: =$BC8*BI83 -> 259.96255 | BJ8: =$BC8*BJ83 -> 303.03887 | BK8: =$BC8*BK83 -> 321.52565 | BL8: =$BC8*BL83 -> 347.85382 | BM8: =Backlog!Y38 -> 1269.5185 | BN8: =$BC8*BN83 -> 244.81495 | BO8: =$BC8*BO83 -> 307.25025 | BP8: =$BC8*BP83 -> 323.17994 | BQ8: =$BC8*BQ83 -> 357.13575 | BR8: =Backlog!Z38 -> 1271.0805
A9: Management Services | F9: 54.131 | G9: 53.788 | H9: 41.255 | I9: =J9-H9-G9-F9 -> 55.352 | J9: 204.526 | K9: 46.035 | L9: 78.439 | M9: 85.482 | N9: =O9-M9-L9-K9 -> 66.019 | O9: 275.975 | P9: 68.112 | Q9: 64.773 | R9: 51.744 | S9: =T9-R9-Q9-P9 -> 56.854 | T9: 241.483 | U9: 47.369 | V9: 45.744 | W9: 37.031 | X9: =Y9-W9-V9-U9 -> 50.932 | Y9: 181.076 | AD9: =SUM(Z9:AC9) -> 0 | AI9: =+SUM(AE9:AH9) -> 0 | AN9: =+SUM(AJ9:AM9) -> 0 | AS9: =+SUM(AO9:AR9) -> 0 | AX9: =+SUM(AT9:AW9) -> 0
A10: Eliminations | M10: -104.024 | N10: =O10-M10-L10-K10 -> -107.095 | O10: -211.119 | P10: -16.942 | Q10: -14.325 | R10: =R11-SUM(R6:R9) -> -9.694 | S10: =S11-SUM(S6:S9) -> -41.687 | T10: =SUM(P10:S10) -> -82.648 | U10: =U11-SUM(U6:U9) -> -65.407 | V10: =V11-SUM(V6:V9) -> -31.304 | W10: =W11-SUM(W6:W9) -> -26.054 | X10: =X11-SUM(X6:X9) -> -26.482 | Y10: -149.247 | Z10: =Z11-SUM(Z6:Z9) -> -24.619 | AA10: =AA11-SUM(AA6:AA9) -> -25.925 | AB10: =X11-SUM(X6:X9) -> -26.482 | AC10: -25.585 | AD10: =SUM(Z10:AC10) -> -102.611 | AE10: -35.491 | AF10: -59.967 | AG10: -95.202 | AH10: -22.583 | AI10: =+SUM(AE10:AH10) -> -213.243 | AJ10: -51.899 | AK10: -61.859 | AL10: -65.53 | AM10: -59.512 | AN10: =+SUM(AJ10:AM10) -> -238.8 | AO10: -51.694 | AP10: -81.904 | AQ10: -69.539 | AR10: -67.765 | AS10: =+SUM(AO10:AR10) -> -270.902 | AT10: -62.662 | AU10: -60.137 | AV10: -49.905 | AW10: -56.638 | AX10: =+SUM(AT10:AW10) -> -229.342 | AY10: -52.905 | AZ10: -72.7 | BA10: -73.233 | BB10: =+BC10-BA10-AZ10-AY10 -> -101.162 | BC10: -300 | BD10: =+BH10/4 -> -77.5 | BE10: =+(BH10-BD10)/3 -> -77.5 | BF10: =+(BH10-BE10-BD10)/2 -> -77.5 | BG10: =+BH10-BF10-BE10-BD10 -> -77.5 | BH10: -310 | BI10: =+BM10/4 -> -77.5 | BJ10: =+(BM10-BI10)/3 -> -77.5 | BK10: =+(BM10-BJ10-BI10)/2 -> -77.5 | BL10: =+BM10-BK10-BJ10-BI10 -> -77.5 | BM10: -310 | BN10: =+BR10/4 -> -77.5 | BO10: =+(BR10-BN10)/3 -> -77.5 | BP10: =+(BR10-BO10-BN10)/2 -> -77.5 | BQ10: =+BR10-BP10-BO10-BN10 -> -77.5 | BR10: -310
A11: Total Revenue | F11: 865.075 | G11: 914.376 | H11: 731.806 | I11: =J11-H11-G11-F11 -> 687.953 | J11: 3199.21 | K11: 615.289 | L11: 819.858 | M11: 1166.41 | N11: =O11-M11-L11-K11 -> 1114.76 | O11: 3716.317 | P11: 912.534 | Q11: 985.346 | R11: 1099.393 | S11: =T11-R11-Q11-P11 -> 1114.198 | T11: 4111.471 | U11: 992.928 | V11: 1053.065 | W11: 1030.388 | X11: =Y11-W11-V11-U11 -> 1099.291 | Y11: 4175.672 | Z11: 955.233 | AA11: 1084.51 | AB11: 1250.689 | AC11: =SUM(AC6:AC10) -> 1201.877 | AD11: =SUM(AD6:AD10) -> 4487.616 | AE11: =SUM(AE6:AE10) -> 1066.465 | AF11: =SUM(AF6:AF10) -> 1312.438 | AG11: =SUM(AG6:AG10) -> 1340.739 | AH11: =SUM(AH6:AH10) -> 1200.83 | AI11: =SUM(AE11:AH11) -> 4920.472 | AJ11: =SUM(AJ6:AJ10) -> 1085.369 | AK11: =SUM(AK6:AK10) -> 1246.271 | AL11: =SUM(AL6:AL10) -> 1332.978 | AM11: =SUM(AM6:AM10) -> 1246.599 | AN11: =SUM(AJ11:AM11) -> 4911.217 | AO11: =SUM(AO6:AO10) -> 1117.361 | AP11: =SUM(AP6:AP10) -> 1247.274 | AQ11: =SUM(AQ6:AQ10) -> 1199.505 | AR11: =SUM(AR6:AR10) -> 1193.068 | AS11: =SUM(AO11:AR11) -> 4757.208 | AT11: =SUM(AT6:AT10) -> 1028.156 | AU11: =SUM(AU6:AU10) -> 1120.085 | AV11: =SUM(AV6:AV10) -> 1123.137 | AW11: =SUM(AW6:AW10) -> 1183.284 | AX11: =SUM(AT11:AW11) -> 4454.662 | AY11: =SUM(AY6:AY10) -> 958.487 | AZ11: =SUM(AZ6:AZ10) -> 1125.275 | BA11: =SUM(BA6:BA10) -> 1189.345 | BB11: =SUM(BB6:BB10) -> 1366.5623 | BC11: =SUM(AY11:BB11) -> 4639.6693 | BD11: =SUM(BD6:BD10) -> 1122.5813 | BE11: =SUM(BE6:BE10) -> 1516.0425 | BF11: =SUM(BF6:BF10) -> 1541.1559 | BG11: =SUM(BG6:BG10) -> 1586.2543 | BH11: =SUM(BD11:BG11) -> 5766.034 | BI11: =SUM(BI6:BI10) -> 1092.666 | BJ11: =SUM(BJ6:BJ10) -> 1526.2034 | BK11: =SUM(BK6:BK10) -> 1529.3986 | BL11: =SUM(BL6:BL10) -> 1617.7661 | BM11: =SUM(BI11:BL11) -> 5766.034 | BN11: =SUM(BN6:BN10) -> 1047.1781 | BO11: =SUM(BO6:BO10) -> 1516.3317 | BP11: =SUM(BP6:BP10) -> 1548.1526 | BQ11: =SUM(BQ6:BQ10) -> 1654.3717 | BR11: =SUM(BN11:BQ11) -> 5766.034
A13: Operating Income by Segment
A14: Building | F14: 32.31 | G14: 29.686 | H14: 28.174 | I14: =J14-H14-G14-F14 -> 5.687 | J14: 95.857 | K14: 13.118 | L14: 24.921 | M14: 8.876 | N14: =O14-M14-L14-K14 -> -0.653 | O14: 46.262 | P14: -8.897 | Q14: -297.095 | R14: 20.847 | S14: =T14-R14-Q14-P14 -> -1.561 | T14: -286.706 | U14: 4.237 | V14: 3.024 | W14: 13.53 | X14: =Y14-W14-V14-U14 -> 3.008 | Y14: 23.799 | Z14: 1.823 | AA14: 7.674 | AB14: 19.159 | AC14: -3.959 | AD14: =SUM(Z14:AC14) -> 24.697 | AE14: -2.279 | AF14: -12.592 | AG14: 6.763 | AH14: 6.867 | AI14: =SUM(AE14:AH14) -> -1.241 | AJ14: 12.45 | AK14: 13.223 | AL14: 13.296 | AM14: 12.596 | AN14: =SUM(AJ14:AM14) -> 51.565 | AO14: 5.242 | AP14: 5.736 | AQ14: 14.058 | AR14: 9.164 | AS14: =SUM(AO14:AR14) -> 34.2 | AT14: 6.425 | AU14: 12.536 | AV14: 8.853 | AW14: 16.125 | AX14: =SUM(AT14:AW14) -> 43.939 | AY14: 3.133 | AZ14: -3.81 | BA14: 7.58 | BB14: =BB6*BB71 -> 10.341669 | BC14: =SUM(AY14:BB14) -> 17.244669 | BD14: =BD6*BD71 -> 15.555679 | BE14: =BE6*BE71 -> 18.283618 | BF14: =BF6*BF71 -> 18.671854 | BG14: =BG6*BG71 -> 20.387179 | BH14: =SUM(BD14:BG14) -> 72.89833 | BI14: =BI6*BI71 -> 15.257677 | BJ14: =BJ6*BJ71 -> 18.362783 | BK14: =BK6*BK71 -> 18.528273 | BL14: =BL6*BL71 -> 20.749596 | BM14: =SUM(BI14:BL14) -> 72.89833 | BN14: =BN6*BN71 -> 14.346121 | BO14: =BO6*BO71 -> 18.286958 | BP14: =BP6*BP71 -> 18.570399 | BQ14: =BQ6*BQ71 -> 21.694852 | BR14: =SUM(BN14:BQ14) -> 72.89833
A15: Civil | F15: 8.29 | G15: 29.72 | H15: 27.298 | I15: =J15-H15-G15-F15 -> 22.474 | J15: 87.782 | K15: 12.114 | L15: 15.283 | M15: 23.805 | N15: =O15-M15-L15-K15 -> 27.344 | O15: 78.546 | P15: 16.842 | Q15: -39.741 | R15: 26.28 | S15: =T15-R15-Q15-P15 -> 43.7 | T15: 47.081 | U15: 21.554 | V15: 29.199 | W15: 47.532 | X15: =Y15-W15-V15-U15 -> 69.583 | Y15: 167.868 | Z15: 44.345 | AA15: 58.002 | AB15: 53.684 | AC15: 64.523 | AD15: =SUM(Z15:AC15) -> 220.554 | AE15: 30.593 | AF15: 46.329 | AG15: 43.183 | AH15: 25.107 | AI15: =SUM(AE15:AH15) -> 145.212 | AJ15: 33.665 | AK15: 45.056 | AL15: 50.307 | AM15: 43.64 | AN15: =SUM(AJ15:AM15) -> 172.668 | AO15: 31.888 | AP15: 58.144 | AQ15: 38.144 | AR15: 64.031 | AS15: =SUM(AO15:AR15) -> 192.207 | AT15: 2.839 | AU15: 49.439 | AV15: 41.282 | AW15: 74.696 | AX15: =SUM(AT15:AW15) -> 168.256 | AY15: 41.745 | AZ15: -164.472 | BA15: 50.695 | BB15: =BB7*BB72 -> 49.284235 | BC15: =SUM(AY15:BB15) -> -22.747765 | BD15: =BD7*BD72 -> 57.429851 | BE15: =BE7*BE72 -> 87.185517 | BF15: =BF7*BF72 -> 86.983884 | BG15: =BG7*BG72 -> 85.626207 | BH15: =SUM(BD15:BG15) -> 317.22546 | BI15: =BI7*BI72 -> 55.519956 | BJ15: =BJ7*BJ72 -> 88.367469 | BK15: =BK7*BK72 -> 86.32744 | BL15: =BL7*BL72 -> 87.010595 | BM15: =SUM(BI15:BL15) -> 317.22546 | BN15: =BN7*BN72 -> 54.727064 | BO15: =BO7*BO72 -> 87.087784 | BP15: =BP7*BP72 -> 88.01233 | BQ15: =BQ7*BQ72 -> 87.398282 | BR15: =SUM(BN15:BQ15) -> 317.22546
A16: Specialty Contractors | M16: 33.132 | N16: =O16-M16-L16-K16 -> 32.45 | O16: 65.582 | P16: 19.748 | Q16: 8.379 | R16: 14.236 | S16: =T16-R16-Q16-P16 -> 25.228 | T16: 67.591 | U16: 19.286 | V16: 15.985 | W16: 9.312 | X16: =Y16-W16-V16-U16 -> 4.425 | Y16: 49.008 | Z16: 7.817 | AA16: 12.633 | AB16: 10.876 | AC16: 19.672 | AD16: =SUM(Z16:AC16) -> 50.998 | AE16: 10.524 | AF16: 13.743 | AG16: 4.741 | AH16: -13.326 | AI16: =SUM(AE16:AH16) -> 15.682 | AJ16: 9.413 | AK16: 5.413 | AL16: 11.084 | AM16: 11.999 | AN16: =SUM(AJ16:AM16) -> 37.909 | AO16: 14.762 | AP16: -14.007 | AQ16: 14.575 | AR16: 3.608 | AS16: =SUM(AO16:AR16) -> 18.938 | AT16: 7.235 | AU16: 7.454 | AV16: 11.561 | AW16: 17.18 | AX16: =SUM(AT16:AW16) -> 43.43 | AY16: -7.488 | AZ16: -159.795 | BA16: 7.247 | BB16: =BB8*BB73 -> 24.063357 | BC16: =SUM(AY16:BB16) -> -135.97264 | BD16: =BD8*BD73 -> 13.211917 | BE16: =BE8*BE73 -> 15.305691 | BF16: =BF8*BF73 -> 16.172078 | BG16: =BG8*BG73 -> 16.929358 | BH16: =SUM(BD16:BG16) -> 61.619045 | BI16: =BI8*BI73 -> 12.998128 | BJ16: =BJ8*BJ73 -> 15.151944 | BK16: =BK8*BK73 -> 16.076282 | BL16: =BL8*BL73 -> 17.392691 | BM16: =SUM(BI16:BL16) -> 61.619045 | BN16: =BN8*BN73 -> 12.240747 | BO16: =BO8*BO73 -> 15.362513 | BP16: =BP8*BP73 -> 16.158997 | BQ16: =BQ8*BQ73 -> 17.856788 | BR16: =SUM(BN16:BQ16) -> 61.619045
A17: Management Services | F17: 3.093 | G17: 6.848 | H17: 2.934 | I17: =J17-H17-G17-F17 -> 9.278 | J17: 22.153 | K17: 2.641 | L17: 6.519 | M17: 5.383 | N17: =O17-M17-L17-K17 -> 7.779 | O17: 22.322 | P17: 1.886 | Q17: -15.122 | R17: 2.841 | S17: =T17-R17-Q17-P17 -> 5.712 | T17: -4.683 | U17: 2.806 | V17: 2.112 | W17: 1.344 | X17: =Y17-W17-V17-U17 -> 4.317 | Y17: 10.579 | AD17: =SUM(Z17:AC17) -> 0 | AI17: =SUM(AE17:AH17) -> 0 | AN17: =SUM(AJ17:AM17) -> 0 | AS17: =SUM(AO17:AR17) -> 0 | AX17: =SUM(AT17:AW17) -> 0 | BC17: =SUM(AY17:BB17) -> 0 | BH17: =SUM(BD17:BG17) -> 0 | BM17: =SUM(BI17:BL17) -> 0 | BR17: =SUM(BN17:BQ17) -> 0
A18: Corporate | F18: -9.536 | G18: -10.403 | H18: -8.446 | I18: =J18-H18-G18-F18 -> -5.095 | J18: -33.48 | K18: -9.36 | L18: -9.688 | M18: -9.16 | N18: =O18-M18-L18-K18 -> -16.128 | O18: -44.336 | P18: -12.616 | Q18: -10.595 | R18: -9.528 | S18: =T18-R18-Q18-P18 -> -12.355 | T18: -45.094 | U18: -11.804 | V18: -10.846 | W18: -13.624 | X18: =Y18-W18-V18-U18 -> -11.158 | Y18: -47.432 | Z18: -12.488 | AA18: -12.866 | AB18: -13.365 | AC18: -15.84 | AD18: =SUM(Z18:AC18) -> -54.559 | AE18: -18.754 | AF18: -16.599 | AG18: -15.713 | AH18: -3.174 | AI18: =SUM(AE18:AH18) -> -54.24 | AJ18: -15.406 | AK18: -14.863 | AL18: -13.768 | AM18: -16.185 | AN18: =SUM(AJ18:AM18) -> -60.222 | AO18: -14.875 | AP18: -15.828 | AQ18: -17.705 | AR18: -17.46 | AS18: =SUM(AO18:AR18) -> -65.868 | AT18: -17.424 | AU18: -14.614 | AV18: -14.39 | AW18: -17.321 | AX18: =SUM(AT18:AW18) -> -63.749 | AY18: -14.447 | AZ18: -13.64 | BA18: -17.579 | BB18: =BB75*-BB11 -> -16.808716 | BC18: =SUM(AY18:BB18) -> -62.474716 | BD18: =BD75*-BD11 -> -13.80775 | BE18: =BE75*-BE11 -> -18.647323 | BF18: =BF75*-BF11 -> -18.956217 | BG18: =BG75*-BG11 -> -19.510928 | BH18: =SUM(BD18:BG18) -> -70.922218 | BI18: =BI75*-BI11 -> -13.439791 | BJ18: =BJ75*-BJ11 -> -18.772302 | BK18: =BK75*-BK11 -> -18.811602 | BL18: =BL75*-BL11 -> -19.898522 | BM18: =SUM(BI18:BL18) -> -70.922218 | BN18: =BN75*-BN11 -> -12.880291 | BO18: =BO75*-BO11 -> -18.650879 | BP18: =BP75*-BP11 -> -19.042277 | BQ18: =BQ75*-BQ11 -> -20.348771 | BR18: =SUM(BN18:BQ18) -> -70.922218
A19: Total Operating Income | F19: =SUM(F14:F18) -> 34.157 | G19: =SUM(G14:G18) -> 55.851 | H19: =SUM(H14:H18) -> 49.96 | I19: =SUM(I14:I18) -> 32.344 | J19: =SUM(J14:J18) -> 172.312 | K19: =SUM(K14:K18) -> 18.513 | L19: =SUM(L14:L18) -> 37.035 | M19: =SUM(M14:M18) -> 62.036 | ... AA19: =SUM(AA14:AA18) -> 65.443 | AB19: =SUM(X14:X18) -> 70.175 | AC19: =SUM(AC14:AC18) -> 64.396 | AD19: =SUM(Z19:AC19) -> 241.511 | AE19: =SUM(AE14:AE18) -> 20.084 | AF19: =SUM(AF14:AF18) -> 30.881 | AG19: =SUM(AG14:AG18) -> 38.974 | AH19: =SUM(AH14:AH18) -> 15.474 | AI19: =SUM(AE19:AH19) -> 105.413 | AJ19: =SUM(AJ14:AJ18) -> 40.122 | AK19: =SUM(AK14:AK18) -> 48.829 | AL19: =SUM(AL14:AL18) -> 60.919 | AM19: =SUM(AM14:AM18) -> 52.05 | AN19: =SUM(AJ19:AM19) -> 201.92 | AO19: =SUM(AO14:AO18) -> 37.017 | AP19: =SUM(AP14:AP18) -> 34.045 | AQ19: =SUM(AQ14:AQ18) -> 49.072 | AR19: =SUM(AR14:AR18) -> 59.343 | AS19: =SUM(AO19:AR19) -> 179.477 | AT19: =SUM(AT14:AT18) -> -0.925 | AU19: =SUM(AU14:AU18) -> 54.815 | AV19: =SUM(AV14:AV18) -> 47.306 | AW19: =SUM(AW14:AW18) -> 90.68 | AX19: =SUM(AT19:AW19) -> 191.876 | AY19: =SUM(AY14:AY18) -> 22.943 | AZ19: =SUM(AZ14:AZ18) -> -341.717 | BA19: =SUM(BA14:BA18) -> 47.943 | BB19: =SUM(BB14:BB18) -> 66.880545 | BC19: =SUM(AY19:BB19) -> -203.95046 | BD19: =SUM(BD14:BD18) -> 72.389698 | BE19: =SUM(BE14:BE18) -> 102.1275 | BF19: =SUM(BF14:BF18) -> 102.8716 | BG19: =SUM(BG14:BG18) -> 103.43182 | BH19: =SUM(BD19:BG19) -> 380.82062 | BI19: =SUM(BI14:BI18) -> 70.335969 | BJ19: =SUM(BJ14:BJ18) -> 103.10989 | BK19: =SUM(BK14:BK18) -> 102.12039 | BL19: =SUM(BL14:BL18) -> 105.25436 | BM19: =SUM(BI19:BL19) -> 380.82062 | BN19: =SUM(BN14:BN18) -> 68.433642 | BO19: =SUM(BO14:BO18) -> 102.08637 | BP19: =SUM(BP14:BP18) -> 103.69945 | BQ19: =SUM(BQ14:BQ18) -> 106.60115 | BR19: =SUM(BN19:BQ19) -> 380.82062
A21: Cost of Operations | F21: 788.942 | G21: 815.464 | H21: 641.136 | I21: =J21-H21-G21-F21 -> 615.82 | J21: 2861.362 | K21: 552.826 | L21: 732.648 | M21: 1046.055 | N21: =O21-M21-L21-K21 -> 989.447 | O21: 3320.976 | P21: 826.375 | Q21: 898.285 | R21: 983.93 | S21: =T21-R21-Q21-P21 -> 987.749 | T21: 3696.339 | U21: 892.571 | V21: 947.11 | W21: 909.531 | X21: =Y21-W21-V21-U21 -> 959.556 | Y21: 3708.768 | Z21: 849.886 | AA21: 954.979 | AB21: 1109.848 | AC21: =(AC11-AC19)-AC22 -> 1137.481 | AD21: =SUM(Z21:AC21) -> 4052.194 | AE21: =(AE11-AE19)-AE22 -> 1046.381 | AF21: =(AF11-AF19)-AF22 -> 1281.557 | AG21: =(AG11-AG19)-AG22 -> 1301.765 | AH21: =(AH11-AH19)-AH22 -> 1185.356 | AI21: =SUM(AE21:AH21) -> 4815.059 | AJ21: =(AJ11-AJ19)-AJ22 -> 1045.247 | AK21: =(AK11-AK19)-AK22 -> 1197.442 | AL21: =(AL11-AL19)-AL22 -> 1272.059 | AM21: =(AM11-AM19)-AM22 -> 1194.549 | AN21: =SUM(AJ21:AM21) -> 4709.297 | AO21: =(AO11-AO19)-AO22 -> 1080.344 | AP21: =(AP11-AP19)-AP22 -> 1213.229 | AQ21: =(AQ11-AQ19)-AQ22 -> 1150.433 | AR21: =(AR11-AR19)-AR22 -> 1133.725 | AS21: =SUM(AO21:AR21) -> 4577.731 | AT21: =(AT11-AT19)-AT22 -> 1029.081 | AU21: =(AU11-AU19)-AU22 -> 1065.27 | AV21: =(AV11-AV19)-AV22 -> 1075.831 | AW21: =(AW11-AW19)-AW22 -> 1092.604 | AX21: =SUM(AT21:AW21) -> 4262.786 | AY21: =(AY11-AY19)-AY22 -> 935.544 | AZ21: =(AZ11-AZ19)-AZ22 -> 1466.992 | BA21: =(BA11-BA19)-BA22 -> 1141.402 | BB21: =(BB11-BB19)-BB22 -> 1299.6817 | BC21: =SUM(AY21:BB21) -> 4843.6197 | BD21: =(BD11-BD19)-BD22 -> 1050.1916 | BE21: =(BE11-BE19)-BE22 -> 1413.915 | BF21: =(BF11-BF19)-BF22 -> 1438.2843 | BG21: =(BG11-BG19)-BG22 -> 1482.8225 | BH21: =SUM(BD21:BG21) -> 5385.2134 | BI21: =(BI11-BI19)-BI22 -> 1022.33 | BJ21: =(BJ11-BJ19)-BJ22 -> 1423.0935 | BK21: =(BK11-BK19)-BK22 -> 1427.2782 | BL21: =(BL11-BL19)-BL22 -> 1512.5117 | BM21: =SUM(BI21:BL21) -> 5385.2134 | BN21: =(BN11-BN19)-BN22 -> 978.74447 | BO21: =(BO11-BO19)-BO22 -> 1414.2453 | BP21: =(BP11-BP19)-BP22 -> 1444.4531 | BQ21: =(BQ11-BQ19)-BQ22 -> 1547.7705 | BR21: =SUM(BN21:BQ21) -> 5385.2134
A23: Goodwill and Intangible Asset Impairment | F23: 0 | G23: 0 | H23: 0 | I23: 0 | J23: 0 | K23: 0 | L23: 0 | M23: 0 | N23: 0 | O23: 0 | P23: 0 | Q23: 376.574 | R23: 0 | S23: 0 | T23: =SUM(P23:S23) -> 376.574 | U23: 0
A24: Income From Construction Operations | F24: =F11-F21-F22 -> 76.133 | G24: =G11-G21-G22 -> 98.912 | H24: =H11-H21-H22 -> 90.67 | I24: =I11-I21-I22 -> 72.133 | J24: =J11-J21-J22 -> 337.848 | K24: =K11-K21-K22 -> 62.463 | L24: =L11-L21-L22 -> 87.21 | M24: =M11-M21-M22 -> 120.355 | ... P24: =P11-P21-P22 -> 86.159 | Q24: =Q11-SUM(Q21:Q23) -> -289.513 | R24: =R11-SUM(R21:R23) -> 115.463 | S24: =S11-SUM(S21:S23) -> 126.449 | T24: =T11-T21-T22-T23 -> 38.558 | U24: =U11-U21-U22 -> 100.357 | V24: =V11-V21-V22 -> 105.955 | W24: =W11-W21-W22 -> 120.857 | X24: =X11-X21-X22 -> 139.735 | Y24: =Y11-Y21-Y22 -> 466.904 | Z24: =Z11-Z21-Z22 -> 105.347 | AA24: =AA11-AA21-AA22 -> 129.531 | AB24: =X11-X21-X22 -> 139.735 | AC24: =AC11-AC21-AC22 -> 64.396 | AD24: =AD11-AD21-AD22 -> 435.422 | AE24: =AE11-AE21-AE22 -> 20.084 | AF24: =AF11-AF21-AF22 -> 30.881 | AG24: =AG11-AG21-AG22 -> 38.974 | AH24: =AH11-AH21-AH22 -> 15.474 | AI24: =AI11-AI21-AI22 -> 105.413 | AJ24: =AJ11-AJ21-AJ22 -> 40.122 | ... BR24: =BR11-BR21-BR22 -> 380.82062
A40: Other Income, net | F40: 0.345 | G40: -1.102 | H40: 0.358 | I40: =J40-H40-G40-F40 -> -1.881 | J40: -2.28 | K40: -0.447 | L40: 1.232 | M40: 5.863 | N40: =O40-M40-L40-K40 -> -2.227 | O40: 4.421 | P40: -2.308 | Q40: 1.082 | R40: 0.545 | S40: =T40-R40-Q40-P40 -> -1.176 | T40: -1.857 | U40: -0.821 | V40: -3.234 | W40: -9.488 | X40: =Y40-W40-V40-U40 -> -5.032 | Y40: -18.575 | Z40: -3.373 | AA40: -6.974 | AB40: -0.441 | AC40: 1.252 | AD40: =SUM(Z40:AC40) -> -9.536 | AE40: -0.754 | AF40: 0.1 | AG40: 5.916 | AH40: 7.192 | AI40: =SUM(AE40:AH40) -> 12.454 | AJ40: 0.682 | AK40: 2.485 | AL40: 2.048 | AM40: 1.763 | AN40: =SUM(AJ40:AM40) -> 6.978 | AO40: 0.417 | AP40: 40.99 | AQ40: 0.967 | AR40: 1.508 | AS40: =SUM(AO40:AR40) -> 43.882 | AT40: 0.78 | AU40: 1.05 | AV40: 1.909 | AW40: 0.517 | AX40: =SUM(AT40:AW40) -> 4.256 | AY40: 0.422 | AZ40: =+(BC40-AY40)/3 -> -0.14066667 | BA40: 1.674 | BB40: =+BC40-BA40-AZ40-AY40 -> -1.9553333 | BC40: 0 | BD40: =+BH40/4 -> 0 | BE40: =+(BH40-BD40)/3 -> 0 | BF40: =+(BH40-BE40-BD40)/2 -> 0 | BG40: =+BH40-BF40-BE40-BD40 -> 0 | BH40: 0 | BI40: =+BM40/4 -> 0 | BJ40: =+(BM40-BI40)/3 -> 0 | BK40: =+(BM40-BJ40-BI40)/2 -> 0 | BL40: =+BM40-BK40-BJ40-BI40 -> 0 | BM40: 0 | BN40: =+BR40/4 -> 0 | BO40: =+(BR40-BN40)/3 -> 0 | BP40: =+(BR40-BO40-BN40)/2 -> 0 | BQ40: =+BR40-BP40-BO40-BN40 -> 0 | BR40: 0
A41: Interest Expense | F41: -1.521 | G41: -3.244 | H41: -1.589 | I41: =J41-H41-G41-F41 -> -4.21 | J41: -10.564 | K41: -7.155 | L41: -7.252 | M41: -11.566 | N41: =O41-M41-L41-K41 -> -9.777 | O41: -35.75 | P41: -11.082 | Q41: -10.603 | R41: -11.039 | S41: =T41-R41-Q41-P41 -> -11.45 | T41: -44.174 | U41: -11.336 | V41: -11.083 | W41: -11.571 | X41: =Y41-W41-V41-U41 -> -11.642 | Y41: -45.632 | Z41: -10.831 | AA41: -10.857 | AB41: -11.297 | AC41: -11.731 | AD41: =SUM(Z41:AC41) -> -44.716 | AE41: -11.125 | AF41: -10.989 | AG41: -10.935 | AH41: -10.979 | AI41: =+SUM(AE41:AH41) -> -44.028 | AJ41: -14.08 | AK41: -15.534 | AL41: -15.041 | AM41: -15.128 | AN41: =SUM(AJ41:AM41) -> -59.783 | AO41: -15.564 | AP41: -22.519 | AQ41: -15.643 | AR41: -15.658 | AS41: =SUM(AO41:AR41) -> -69.384 | AT41: -15.065 | AU41: -15.998 | AV41: -16.411 | AW41: -16.045 | AX41: =SUM(AT41:AW41) -> -63.519 | AY41: -16.425 | AZ41: =+(BC41-AY41)/3 -> -14.525 | BA41: -17.305 | BB41: =+BC41-BA41-AZ41-AY41 -> -11.745 | BC41: -60 | BD41: =+BH41/4 -> -13.75 | BE41: =+(BH41-BD41)/3 -> -13.75 | BF41: =+(BH41-BE41-BD41)/2 -> -13.75 | BG41: =+BH41-BF41-BE41-BD41 -> -13.75 | BH41: -55 | BI41: =+BM41/4 -> -13.75 | BJ41: =+(BM41-BI41)/3 -> -13.75 | BK41: =+(BM41-BJ41-BI41)/2 -> -13.75 | BL41: =+BM41-BK41-BJ41-BI41 -> -13.75 | BM41: -55 | BN41: =+BR41/4 -> -13.75 | BO41: =+(BR41-BN41)/3 -> -13.75 | BP41: =+(BR41-BO41-BN41)/2 -> -13.75 | BQ41: =+BR41-BP41-BO41-BN41 -> -13.75 | BR41: -55
A43: EBITDA | AJ43: =AJ44+CF!AJ8 -> 41.22 | AK43: =AK44+CF!AK8 -> 51.24 | AL43: =AL44+CF!AL8 -> 65.265 | AM43: =AM44+CF!AM8 -> 58.692 | AN43: =AN44+CF!AN8 -> 216.417 | AO43: =AO44+CF!AO8 -> 42.866 | AP43: =AP44+CF!AP8 -> 62.278 | AQ43: =AQ44+CF!AQ8 -> 44.101 | ... BR43: =BR44+CF!BR8 -> 390.82062
A44: Income Before Taxes | F44: =F24+F40+F41 -> 74.957 | G44: =G24+G40+G41 -> 94.566 | H44: =H24+H40+H41 -> 89.439 | I44: =I24+I40+I41 -> 66.042 | J44: =J41+J40+J24 -> 325.004 | K44: =K24+K40+K41 -> 54.861 | L44: =L24+L40+L41 -> 81.19 | M44: =M24+M40+M41 -> 114.652 | N44: =N24+N40+N41 -> 113.309 | O44: =O41+O40+O24 -> 364.012 | P44: =P24+P40+P41 -> 72.769 | Q44: =Q24+Q40+Q41 -> -299.034 | R44: =R24+R40+R41 -> 104.969 | S44: =S24+S40+S41 -> 113.823 | T44: =T41+T40+T24 -> -7.473 | U44: =U24+U40+U41 -> 88.2 | V44: =V24+V40+V41 -> 91.638 | W44: =W24+W40+W41 -> 99.798 | X44: =X24+X40+X41 -> 123.061 | Y44: =Y41+Y40+Y24 -> 402.697 | Z44: =Z19+Z40+Z41 -> 27.293 | AA44: =AA19+AA40+AA41 -> 47.612 | AB44: =X19+X40+X41 -> 53.501 | AC44: =AC19+AC40+AC41 -> 53.917 | AD44: =SUM(Z44:AC44) -> 182.323 | AE44: =AE19+AE40+AE41 -> 8.205 | AF44: =AF19+AF40+AF41 -> 19.992 | AG44: =AG19+AG40+AG41 -> 33.955 | AH44: =AH19+AH40+AH41 -> 11.687 | AI44: =AI41+AI40+AI19 -> 73.839 | AJ44: =AJ19+AJ40+AJ41 -> 26.724 | AK44: =AK19+AK40+AK41 -> 35.78 | AL44: =AL19+AL40+AL41 -> 47.926 | AM44: =AM19+AM40+AM41 -> 38.685 | AN44: =AN41+AN40+AN19 -> 149.115 | AO44: =AO19+AO40+AO41 -> 21.87 | AP44: =AP19+AP40+AP41 -> 52.516 | AQ44: =AQ19+AQ40+AQ41 -> 34.396 | AR44: =AR19+AR40+AR41 -> 45.193 | AS44: =AS41+AS40+AS19 -> 153.975 | AT44: =AT19+AT40+AT41 -> -15.21 | AU44: =AU19+AU40+AU41 -> 39.867 | AV44: =AV19+AV40+AV41 -> 32.804 | AW44: =AW19+AW40+AW41 -> 75.152 | AX44: =AX41+AX40+AX19 -> 132.613 | AY44: =AY19+AY40+AY41 -> 6.94 | AZ44: =AZ19+AZ40+AZ41 -> -356.38267 | BA44: =BA19+BA40+BA41 -> 32.312 | BB44: =BB19+BB40+BB41 -> 53.180212 | BC44: =BC41+BC40+BC19 -> -263.95046 | BD44: =BD19+BD40+BD41 -> 58.639698 | BE44: =BE19+BE40+BE41 -> 88.377503 | BF44: =BF19+BF40+BF41 -> 89.121599 | BG44: =BG19+BG40+BG41 -> 89.681816 | BH44: =BH41+BH40+BH19 -> 325.82062 | BI44: =BI19+BI40+BI41 -> 56.585969 | BJ44: =BJ19+BJ40+BJ41 -> 89.359894 | BK44: =BK19+BK40+BK41 -> 88.370393 | BL44: =BL19+BL40+BL41 -> 91.504359 | BM44: =BM41+BM40+BM19 -> 325.82062 | BN44: =BN19+BN40+BN41 -> 54.683642 | BO44: =BO19+BO40+BO41 -> 88.336375 | BP44: =BP19+BP40+BP41 -> 89.949449 | BQ44: =BQ19+BQ40+BQ41 -> 92.851151 | BR44: =BR41+BR40+BR19 -> 325.82062
A45: Provision for Income Taxes | F45: -12.048 | G45: -18.78 | H45: -17.796 | I45: =J45-H45-G45-F45 -> -7.344 | J45: -55.968 | K45: -3.982 | L45: -11.321 | M45: -20.856 | N45: =O45-M45-L45-K45 -> -14.74 | O45: -50.899 | P45: -4.776 | Q45: 15.272 | R45: -1.591 | S45: =T45-R45-Q45-P45 -> -6.463 | T45: 2.442 | U45: -9.116 | V45: -9.679 | W45: -13.276 | X45: =Y45-W45-V45-U45 -> -20.248 | Y45: -52.319 | Z45: -11.354 | AA45: -19.067 | AB45: -22.886 | AC45: -26.195 | AD45: =SUM(Z45:AC45) -> -79.502 | AE45: -3.079 | AF45: -8.215 | AG45: -14.278 | AH45: -2.975 | AI45: =SUM(AE45:AH45) -> -28.547 | AJ45: -11.324 | AK45: -14.419 | AL45: -19.125 | AM45: -8.425 | AN45: =SUM(AJ45:AM45) -> -53.293 | AO45: -8.106 | AP45: -19.883 | AQ45: -9.096 | AR45: 37.654 | AS45: =SUM(AO45:AR45) -> 0.569 | AT45: 4.268 | AU45: -11.971 | AV45: -7.368 | AW45: -19.761 | AX45: =SUM(AT45:AW45) -> -34.832 | AY45: -2.188 | AZ45: 42.9 | BA45: -5.591 | BB45: =BB44*BB78 -> -15.422261 | BC45: =SUM(AY45:BB45) -> 19.698739 | BD45: =BD44*BD78 -> -17.005512 | BE45: =BE44*BE78 -> -25.629476 | BF45: =BF44*BF78 -> -25.845264 | BG45: =BG44*BG78 -> -26.007727 | BH45: =SUM(BD45:BG45) -> -94.487979 | BI45: =BI44*BI78 -> -16.409931 | BJ45: =BJ44*BJ78 -> -25.914369 | BK45: =BK44*BK78 -> -25.627414 | BL45: =BL44*BL78 -> -26.536264 | BM45: =SUM(BI45:BL45) -> -94.487979 | BN45: =BN44*BN78 -> -15.858256 | BO45: =BO44*BO78 -> -25.617549 | BP45: =BP44*BP78 -> -26.08534 | BQ45: =BQ44*BQ78 -> -26.926834 | BR45: =SUM(BN45:BQ45) -> -94.487979
A47: NCI | AP47: -2.537 | AQ47: -1.716 | AR47: -1.909 | AS47: =+SUM(AO47:AR47) -> -6.162 | AT47: -1.182 | AU47: -3.013 | AV47: -4.164 | AW47: -5.986 | AX47: =+SUM(AT47:AW47) -> -14.345 | AY47: -5.078 | AZ47: -5.091 | BA47: -7.408 | BB47: =BA47 -> -7.408 | BC47: =SUM(AY47:BB47) -> -24.985 | BD47: -4 | BE47: =BD47 -> -4 | BF47: =BE47 -> -4 | BG47: =BF47 -> -4 | BH47: =SUM(BD47:BG47) -> -16 | BI47: -4 | BJ47: =BI47 -> -4 | BK47: =BJ47 -> -4 | BL47: =BK47 -> -4 | BM47: =SUM(BI47:BL47) -> -16 | BN47: -4 | BO47: =BN47 -> -4 | BP47: =BO47 -> -4 | BQ47: =BP47 -> -4 | BR47: =SUM(BN47:BQ47) -> -16
A48: Net Income | F48: =F44+F45 -> 62.909 | G48: =G44+G45 -> 75.786 | H48: =H44+H45 -> 71.643 | I48: =I44+I45 -> 58.698 | J48: =J44+J45 -> 269.036 | K48: =K44+K45 -> 50.879 | L48: =L44+L45 -> 69.869 | M48: =M44+M45 -> 93.796 | ... AA48: =AA44+AA45 -> 28.545 | AB48: =X44+X45 -> 102.813 | AC48: =AC44+AC45 -> 27.722 | AD48: =AD44+AD45 -> 102.821 | AE48: =AE44+AE45 -> 5.126 | AF48: =AF44+AF45 -> 11.777 | AG48: =AG44+AG45 -> 19.677 | AH48: =AH44+AH45 -> 8.712 | AI48: =AI44+AI45 -> 45.292 | AJ48: =AJ44+AJ45 -> 15.4 | ... AO48: =AO44+AO45 -> 13.764 | AP48: =AP44+AP45+AP47 -> 30.096 | AQ48: =AQ44+AQ45+AQ47 -> 23.584 | AR48: =AR44+AR45+AR47 -> 80.938 | AS48: =AS44+AS45+AS47 -> 148.382 | AT48: =AT44+AT45+AT47 -> -12.124 | AU48: =AU44+AU45+AU47 -> 24.883 | AV48: =AV44+AV45+AV47 -> 21.272 | AW48: =AW44+AW45+AW47 -> 49.405 | ... BR48: =BR44+BR45+BR47 -> 215.33264
A50: Basic EPS | F50: =F48/F53 -> 1.2832024 | G50: =G48/G53 -> 1.5466215 | H50: =H48/H53 -> 1.5128281 | I50: =I48/I53 -> 1.2200536 | J50: =J48/J53 -> 5.5919852 | K50: =K48/K53 -> 1.0802335 | L50: =L48/L53 -> 1.4808088 | M50: =M48/M53 -> 1.9833795 | ... AA50: =AA48/AA53 -> 0.58803535 | AB50: =X48/X53 -> 2.1486071 | AC50: =AC48/AC53 -> 0.56957942 | AD50: =AD48/AD53 -> 2.1173794 | AE50: =AE48/AE53 -> 0.10515519 | AF50: =AF48/AF53 -> 0.24020968 | AG50: =AG48/AG53 -> 0.40099857 | AH50: =AH48/AH53 -> 0.17753143 | AI50: =AI48/AI53 -> 0.92468508 | AJ50: =AJ48/AJ53 -> 0.31377982 | ... BR50: =BR48/BR53 -> 4.282755
A51: Diluted EPS | F51: =F48/F54 -> 1.2744419 | G51: =G48/G54 -> 1.5299176 | H51: =H48/H54 -> 1.4958034 | I51: =I48/I54 -> 1.2065613 | J51: =J48/J54 -> 5.5301445 | K51: =K48/K54 -> 1.0630354 | L51: =L48/L54 -> 1.4568486 | M51: =M48/M54 -> 1.9637384 | ... AA51: =AA48/AA54 -> 0.5819216 | AB51: =X48/X54 -> 2.1159728 | AC51: =AC48/AC54 -> 0.56124226 | AD51: =AD48/AD54 -> 2.0935597 | AE51: =AE48/AE54 -> 0.10346568 | AF51: =AF48/AF54 -> 0.23635305 | AG51: =AG48/AG54 -> 0.39531894 | AH51: =AH48/AH54 -> 0.17595734 | AI51: =AI48/AI54 -> 0.9119317 | AJ51: =AJ48/AJ54 -> 0.3124683 | ... BR51: =BR48/BR54 -> 4.2571001
A53: Basic Shares | F53: 49.025 | G53: 49.001 | H53: 47.357 | I53: 48.111 | J53: 48.111 | K53: 47.1 | L53: 47.183 | M53: 47.291 | N53: =O53 -> 47.226 | O53: 47.226 | P53: 47.33 | Q53: 47.434 | R53: 47.556 | S53: 47.47 | T53: 47.47 | U53: 47.559 | V53: 47.684 | W53: 47.959 | X53: =Y53 -> 47.851 | Y53: 47.851 | Z53: 48.44 | AA53: 48.543 | AB53: 48.588 | AC53: 48.671 | AD53: =AVERAGE(Z53:AC53) -> 48.5605 | AE53: 48.747 | AF53: 49.028 | AG53: 49.07 | AH53: 49.073 | AI53: 48.981 | AJ53: 49.079 | AK53: 49.131 | AL53: 49.185 | AM53: 49.202 | AN53: =+AVERAGE(AJ53:AM53) -> 49.14925 | AO53: 49.282 | AP53: 49.735 | AQ53: =AP53 -> 49.735 | AR53: 49.781 | AS53: =+AVERAGE(AO53:AR53) -> 49.63325 | AT53: 49.814 | AU53: 49.946 | AV53: 50.018 | AW53: 49.952 | AX53: =+AVERAGE(AT53:AW53) -> 49.9325 | AY53: 50.098 | AZ53: 50.224 | BA53: 50.279 | BB53: =BA53 -> 50.279 | BC53: =+AVERAGE(AY53:BB53) -> 50.22 | BD53: =BB53 -> 50.279 | BE53: =BD53 -> 50.279 | BF53: =BE53 -> 50.279 | BG53: =BF53 -> 50.279 | BH53: =+AVERAGE(BD53:BG53) -> 50.279 | BI53: =BG53 -> 50.279 | BJ53: =BI53 -> 50.279 | BK53: =BJ53 -> 50.279 | BL53: =BK53 -> 50.279 | BM53: =+AVERAGE(BI53:BL53) -> 50.279 | BN53: =BL53 -> 50.279 | BO53: =BN53 -> 50.279 | BP53: =BO53 -> 50.279 | BQ53: =BP53 -> 50.279 | BR53: =+AVERAGE(BN53:BQ53) -> 50.279
A54: Diluted Shares | F54: 49.362 | G54: 49.536 | H54: 47.896 | I54: =J54 -> 48.649 | J54: 48.649 | K54: 47.862 | L54: 47.959 | M54: 47.764 | N54: =O54 -> 47.89 | O54: 47.89 | P54: 47.33 | Q54: 47.434 | R54: 48.217 | S54: =T54 -> 47.47 | T54: 47.47 | U54: 48.513 | V54: 48.598 | W54: 48.625 | X54: =Y54 -> 48.589 | Y54: 48.589 | Z54: 48.93 | AA54: 49.053 | AB54: 49.075 | AC54: 49.394 | AD54: =AVERAGE(Z54:AC54) -> 49.113 | AE54: 49.543 | AF54: 49.828 | AG54: 49.775 | AH54: 49.512 | AI54: 49.666 | AJ54: 49.285 | AK54: 49.561 | AL54: 50.1 | AM54: 50.507 | AN54: =+AVERAGE(AJ54:AM54) -> 49.86325 | AO54: 50.948 | AP54: 50.755 | AQ54: =AP54 -> 50.755 | AR54: 50.732 | AS54: =+AVERAGE(AO54:AR54) -> 50.7975 | AT54: 49.814 | AU54: 49.946 | AV54: 50.375 | AW54: 50.301 | AX54: =+AVERAGE(AT54:AW54) -> 50.109 | AY54: 50.098 | AZ54: 50.224 | BA54: 50.582 | BB54: =BA54 -> 50.582 | BC54: =+AVERAGE(AY54:BB54) -> 50.3715 | BD54: =BB54 -> 50.582 | BE54: =BD54 -> 50.582 | BF54: =BE54 -> 50.582 | BG54: =BF54 -> 50.582 | BH54: =+AVERAGE(BD54:BG54) -> 50.582 | BI54: =BG54 -> 50.582 | BJ54: =BI54 -> 50.582 | BK54: =BJ54 -> 50.582 | BL54: =BK54 -> 50.582 | BM54: =+AVERAGE(BI54:BL54) -> 50.582 | BN54: =BL54 -> 50.582 | BO54: =BN54 -> 50.582 | BP54: =BO54 -> 50.582 | BQ54: =BP54 -> 50.582 | BR54: =+AVERAGE(BN54:BQ54) -> 50.582
AI55: =0.53+0.28+0.2-0.16 -> 0.85
A57: Drivers
A58: Building | K58: =K6/F6-1 -> -0.3582409 | L58: =L6/G6-1 -> -0.095271557 | M58: =M6/H6-1 -> 0.090277738 | N58: =N6/I6-1 -> -0.24716111 | P58: =P6/K6-1 -> -0.22112531 | Q58: =Q6/L6-1 -> -0.44677213 | R58: =R6/M6-1 -> -0.31029143 | S58: =S6/N6-1 -> 0.19789619 | U58: =U6/P6-1 -> 0.23925851 | V58: =V6/Q6-1 -> 0.27247804 | W58: =W6/R6-1 -> -0.10093198 | X58: =X6/S6-1 -> -0.18028514 | Z58: =Z6/U6-1 -> -0.26769055 | AA58: =AA6/V6-1 -> -0.075794453 | AB58: =X6/W6-1 -> -0.040563843 | AC58: =AC6/X6-1 -> 0.29201976 | AE58: =AE6/Z6-1 -> 0.33646949 | AF58: =AF6/AA6-1 -> 0.20979472 | AG58: =AG6/X6-1 -> 0.49898737 | AH58: =AH6/AC6-1 -> 0.15942149 | AJ58: =AJ6/AE6-1 -> 0.17288488 | AK58: =AK6/AF6-1 -> 0.10857454 | AL58: =AL6/AG6-1 -> 0.10772352 | AM58: =AM6/AH6-1 -> 0.090679628 | AO58: =AO6/AJ6-1 -> 0.055855195 | AP58: =AP6/AK6-1 -> -0.02817843 | AQ58: =AQ6/AL6-1 -> -0.10765966 | AR58: -0.02 | AS58: =AS6/AN6-1 -> -0.064577604 | AT58: =AT6/AO6-1 -> -0.047809708 | AU58: =AU6/AP6-1 -> -0.11949234 | AV58: =AV6/AQ6-1 -> -0.086159626 | AW58: =AW6/AR6-1 -> 0.018389149 | AX58: =AX6/AS6-1 -> -0.060413973 | AY58: =AY6/AT6-1 -> -0.11082779 | AZ58: =AZ6/AU6-1 -> -0.032180367 | ... BR58: =BR6/BM6-1 -> 0.0065517926
A59: Civil | K59: =K7/F7-1 -> 0.033410878 | L59: =L7/G7-1 -> -0.28358768 | M59: =M7/H7-1 -> 0.65619849 | N59: =N7/I7-1 -> 0.96476473 | P59: =P7/K7-1 -> 0.94518921 | Q59: =Q7/L7-1 -> 1.3124107 | R59: =R7/M7-1 -> 0.24590642 | S59: =S7/N7-1 -> 0.04962146 | U59: =U7/P7-1 -> 0.13323011 | V59: =V7/Q7-1 -> 0.015748826 | W59: =W7/R7-1 -> 0.083365189 | X59: =X7/S7-1 -> 0.18046561 | Z59: =Z7/U7-1 -> 0.32544062 | AA59: =AA7/V7-1 -> 0.19836074 | AB59: =X7/W7-1 -> 0.12650982 | AC59: =AC7/X7-1 -> 0.07480441 | AE59: =AE7/Z7-1 -> 0.043794767 | AF59: =AF7/AA7-1 -> 0.44015794 | AG59: =AG7/X7-1 -> 0.41258599 | AH59: =AH7/AC7-1 -> -0.054742057 | AJ59: =AJ7/AE7-1 -> -0.064587809 | AK59: =AK7/AF7-1 -> -0.18775813 | AL59: =AL7/AG7-1 -> -0.16252563 | AM59: =AM7/AH7-1 -> 0.040693447 | AO59: =AO7/AJ7-1 -> -0.079980735 | AP59: =AP7/AK7-1 -> 0.15641809 | AQ59: =AQ7/AL7-1 -> -0.094078245 | AR59: =AR7/AM7-1 -> 0.088402859 | AS59: =AS7/AN7-1 -> 0.01999626 | AT59: =AT7/AO7-1 -> -0.037585624 | AU59: =AU7/AP7-1 -> -0.14286086 | AV59: =AV7/AQ7-1 -> 0.046007848 | ... BR59: =BR7/BM7-1 -> 0.21724215
A60: Specialty Contractors | K60: =K8/F8-1 -> #DIV/0! | L60: =L8/G8-1 -> #DIV/0! | M60: =M8/H8-1 -> #DIV/0! | N60: =N8/I8-1 -> #DIV/0! | P60: =P8/K8-1 -> #DIV/0! | Q60: =Q8/L8-1 -> #DIV/0! | R60: =R8/M8-1 -> -0.061475764 | S60: =S8/N8-1 -> -0.30432863 | U60: =U8/P8-1 -> 0.12751741 | V60: =V8/Q8-1 -> 0.029481483 | W60: =W8/R8-1 -> -0.08766137 | X60: =X8/S8-1 -> -0.047170451 | Z60: =Z8/U8-1 -> -0.032238296 | AA60: =AA8/V8-1 -> 0.13351477 | AB60: =X8/W8-1 -> 0.075321677 | AC60: =AC8/X8-1 -> 0.071109416 | AE60: =AE8/Z8-1 -> 0.0029848192 | AF60: =AF8/AA8-1 -> 0.015029864 | AG60: =AG8/X8-1 -> 0.051946666 | AH60: =AH8/AC8-1 -> -0.14622448 | AJ60: =AJ8/AE8-1 -> -0.0383732 | AK60: =AK8/AF8-1 -> -0.024161715 | AL60: =AL8/AG8-1 -> 0.019203049 | AM60: =AM8/AH8-1 -> 0.067647402 | AO60: =AO8/AJ8-1 -> 0.12039124 | AP60: =AP8/AK8-1 -> -0.11616421 | AQ60: -0.05 | AR60: =AR8/AM8-1 -> 0.013361679 | AS60: =AS8/AN8-1 -> -0.016660037 | AT60: =AT8/AO8-1 -> -0.12953918 | AU60: =AU8/AP8-1 -> -0.039821612 | AV60: =AV8/AQ8-1 -> -0.23853974 | AW60: =AW8/AR8-1 -> -0.26383742 | AX60: =AX8/AS8-1 -> -0.17041826 | AY60: =AY8/AT8-1 -> -0.30303383 | ... BR60: =BR8/BM8-1 -> 0.0012304342
A61: Management Services | K61: =K9/F9-1 -> -0.1495631 | L61: =L9/G9-1 -> 0.45829925 | M61: =M9/H9-1 -> 1.0720398 | N61: =N9/I9-1 -> 0.1927121 | P61: =P9/K9-1 -> 0.47956989 | Q61: =Q9/L9-1 -> -0.17422456 | R61: =R9/M9-1 -> -0.39467958 | S61: =S9/N9-1 -> -0.13882367 | U61: =U9/P9-1 -> -0.30454252 | V61: =V9/Q9-1 -> -0.29377982 | W61: =W9/R9-1 -> -0.28434215 | X61: =X9/S9-1 -> -0.10416154 | Z61: =Z9/U9-1 -> -1 | AA61: =AA9/V9-1 -> -1 | AB61: =X9/W9-1 -> 0.37538819 | AC61: =AC9/X9-1 -> -1 | AE61: =AE9/Z9-1 -> #DIV/0! | AF61: =AF9/AA9-1 -> #DIV/0! | AG61: =AG9/X9-1 -> -1 | AH61: =AH9/AC9-1 -> #DIV/0! | AJ61: =AJ9/AE9-1 -> #DIV/0! | AK61: =AK9/AF9-1 -> #DIV/0! | AL61: =AL9/AG9-1 -> #DIV/0! | AM61: =AM9/AH9-1 -> #DIV/0! | AO61: =AO9/AJ9-1 -> #DIV/0! | AP61: =AP9/AK9-1 -> #DIV/0! | AQ61: =AQ9/AL9-1 -> #DIV/0! | AR61: =AR9/AM9-1 -> #DIV/0! | AS61: =AS9/AN9-1 -> #DIV/0! | AT61: =AT9/AO9-1 -> #DIV/0! | AU61: =AU9/AP9-1 -> #DIV/0! | AV61: =AV9/AQ9-1 -> #DIV/0! | ... BR61: =BR9/BM9-1 -> #DIV/0!
A62: Eliminations (% of construction revenue) | M62: =-M10/SUM(M6:M9) -> 0.08188068 | N62: =-N10/SUM(N6:N9) -> 0.087649517 | P62: =-P10/SUM(P6:P9) -> 0.018227474 | Q62: =-Q10/SUM(Q6:Q9) -> 0.014329714 | R62: =-R10/SUM(R6:R9) -> 0.0087405226 | S62: =-S10/SUM(S6:S9) -> 0.036065006 | U62: =-U10/SUM(U6:U9) -> 0.061801792 | V62: =-V10/SUM(V6:V9) -> 0.028868402 | W62: =-W10/SUM(W6:W9) -> 0.024662026 | X62: =-X10/SUM(X6:X9) -> 0.023523392 | Z62: =-Z10/SUM(Z6:Z9) -> 0.025125223 | AA62: =-AA10/SUM(AA6:AA9) -> 0.023346706 | AB62: =-X10/SUM(X6:X9) -> 0.023523392 | AC62: =-AC10/SUM(AC6:AC9) -> 0.020843822 | AE62: =-AE10/SUM(AE6:AE9) -> 0.032207275 | AF62: =-AF10/SUM(AF6:AF9) -> 0.043694828 | AG62: =-AG10/SUM(AG6:AG9) -> 0.066299381 | AH62: =-AH10/SUM(AH6:AH9) -> 0.018459016 | AJ62: =-AJ10/SUM(AJ6:AJ9) -> 0.045634802 | AK62: =-AK10/SUM(AK6:AK9) -> 0.047288114 | AL62: =-AL10/SUM(AL6:AL9) -> 0.046857079 | AM62: =-AM10/SUM(AM6:AM9) -> 0.045564274 | AO62: =-AO10/SUM(AO6:AO9) -> 0.044218621 | AP62: =-AP10/SUM(AP6:AP9) -> 0.061620039 | AQ62: =-AQ10/SUM(AQ6:AQ9) -> 0.054796366 | AR62: =-AR10/SUM(AR6:AR9) -> 0.053746214 | AS62: =-AS10/SUM(AS6:AS9) -> 0.053877501 | AT62: =-AT10/SUM(AT6:AT9) -> 0.057444963 | AU62: =-AU10/SUM(AU6:AU9) -> 0.050953973 | AV62: =-AV10/SUM(AV6:AV9) -> 0.042543234 | ... BR62: =-BR10/SUM(BR6:BR9) -> 0.034803042
A63: Revenue | K63: =K11/F11-1 -> -0.28874491 | L63: =L11/G11-1 -> -0.10336885 | M63: =M11/H11-1 -> 0.59387871 | N63: =N11/I11-1 -> 0.62040139 | P63: =P11/K11-1 -> 0.48309819 | Q63: =Q11/L11-1 -> 0.20184959 | R63: =R11/M11-1 -> -0.057455783 | S63: =S11/N11-1 -> -0.00050414439 | U63: =U11/P11-1 -> 0.088099731 | V63: =V11/Q11-1 -> 0.068726112 | W63: =W11/R11-1 -> -0.062766454 | X63: =X11/S11-1 -> -0.01337913 | Z63: =Z11/U11-1 -> -0.037963478 | AA63: =AA11/V11-1 -> 0.029860455 | AB63: =X11/W11-1 -> 0.066870926 | AC63: =AC11/X11-1 -> 0.093320149 | AE63: =AE11/Z11-1 -> 0.11644489 | AF63: =AF11/AA11-1 -> 0.2101668 | AG63: =AG11/X11-1 -> 0.21963975 | AH63: =AH11/AC11-1 -> -0.0008711374 | AJ63: =AJ11/AE11-1 -> 0.017725851 | AK63: =AK11/AF11-1 -> -0.050415334 | AL63: =AL11/AG11-1 -> -0.0057885987 | AM63: =AM11/AH11-1 -> 0.038114471 | AN63: =+AN11/AI11-1 -> -0.0018809171 | AO63: =AO11/AJ11-1 -> 0.02947569 | AP63: =AP11/AK11-1 -> 0.00080480088 | AQ63: =AQ11/AL11-1 -> -0.10013144 | AR63: =AR11/AM11-1 -> -0.042941636 | AS63: =AS11/AN11-1 -> -0.031358623 | AT63: =AT11/AO11-1 -> -0.079835434 | AU63: =AU11/AP11-1 -> -0.10197358 | AV63: =AV11/AQ11-1 -> -0.063666262 | ... BR63: =BR11/BM11-1 -> 0
...

Sheet BS
A1: Tutor Perini | AC1: =CF!AC17 -> -8.35 | AD1: =CF!AD17 -> 51.71 | AE1: =CF!AE17 -> -33.254 | AF1: =CF!AF17 -> -22.642 | AG1: =CF!AG17 -> 23.165 | AH1: =CF!AH17 -> 1.746 | AI1: =CF!AI17 -> -30.985 | AJ1: =CF!AJ17 -> -2.729 | ... AS1: =CF!AS17 -> 125.757 | AT1: =CF!BD17 -> 9.8456573 | AU1: =CF!BE17 -> 23.446052 | AV1: =CF!BF17 -> 21.108651 | AW1: =CF!BG17 -> 13.181523 | AX1: =CF!BH17 -> 67.581884 | AY1: =CF!BI17 -> -1.7949194 | AZ1: =CF!BJ17 -> 0.60965244 | BA1: =CF!BK17 -> -0.70543694 | ... BC1: =CF!BM17 -> 0
A2: Balance Sheet | F2: 40268 | G2: =+EOMONTH(F2,3) -> 40359 | H2: =+EOMONTH(G2,3) -> 40451 | I2: =+EOMONTH(H2,3) -> 40543 | K2: =+EOMONTH(F2,12) -> 40633 | L2: =+EOMONTH(G2,12) -> 40724 | M2: =+EOMONTH(H2,12) -> 40816 | N2: =+EOMONTH(I2,12) -> 40908 | P2: =EOMONTH(K2,12) -> 40999 | Q2: =EOMONTH(L2,12) -> 41090 | R2: =EOMONTH(M2,12) -> 41182 | S2: =EOMONTH(N2,12) -> 41274 | U2: =EOMONTH(P2,12) -> 41364 | V2: =EOMONTH(Q2,12) -> 41455 | W2: =EOMONTH(R2,12) -> 41547 | X2: =EOMONTH(S2,12) -> 41639 | Z2: =EOMONTH(U2,12) -> 41729 | AA2: =EOMONTH(V2,12) -> 41820 | AB2: =EOMONTH(W2,12) -> 41912 | AC2: =EOMONTH(X2,12) -> 42004 | AE2: =EOMONTH(Z2,12) -> 42094 | AF2: =EOMONTH(AA2,12) -> 42185 | AG2: =EOMONTH(AB2,12) -> 42277 | AH2: =EOMONTH(AC2,12) -> 42369 | AJ2: =EOMONTH(AE2,12) -> 42460 | AK2: =EOMONTH(AF2,12) -> 42551 | AL2: =EOMONTH(AG2,12) -> 42643 | AM2: =EOMONTH(AH2,12) -> 42735 | AO2: =EOMONTH(AJ2,12) -> 42825 | AP2: =EOMONTH(AK2,12) -> 42916 | AQ2: =EOMONTH(AL2,12) -> 43008 | AR2: =EOMONTH(AM2,12) -> 43100 | AT2: =EOMONTH(AO2,12) -> 43190 | AU2: =EOMONTH(AP2,12) -> 43281 | AV2: =EOMONTH(AQ2,12) -> 43373 | AW2: =EOMONTH(AR2,12) -> 43465 | AY2: =EOMONTH(AT2,12) -> 43555 | AZ2: =EOMONTH(AU2,12) -> 43646 | BA2: =EOMONTH(AV2,12) -> 43738 | BB2: =EOMONTH(AW2,12) -> 43830 | BD2: =EOMONTH(AY2,12) -> 43921 | BE2: =EOMONTH(AZ2,12) -> 44012 | BF2: =EOMONTH(BA2,12) -> 44104 | BG2: =EOMONTH(BB2,12) -> 44196 | BI2: =EOMONTH(BD2,12) -> 44286 | BJ2: =EOMONTH(BE2,12) -> 44377 | BK2: =EOMONTH(BF2,12) -> 44469 | BL2: =EOMONTH(BG2,12) -> 44561 | BN2: =EOMONTH(BI2,12) -> 44651 | BO2: =EOMONTH(BJ2,12) -> 44742 | BP2: =EOMONTH(BK2,12) -> 44834 | BQ2: =EOMONTH(BL2,12) -> 44926
A3: TPC | F3: 2010 | J3: =+F3 -> 2010 | K3: 2011 | O3: =+K3 -> 2011 | P3: 2012 | T3: =+P3 -> 2012 | U3: 2013 | Y3: =+U3 -> 2013 | Z3: 2014 | AD3: =+Z3 -> 2014 | AE3: 2015 | AI3: =+AE3 -> 2015 | AJ3: 2016 | AN3: =+AJ3 -> 2016 | AO3: 2017 | AS3: =+AO3 -> 2017 | AT3: 2018 | AX3: =+AT3 -> 2018 | AY3: 2019E | BC3: =+AY3 -> 2019E | BD3: 2020E | BH3: =+BD3 -> 2020E | BI3: 2021E | BM3: =+BI3 -> 2021E | BN3: 2022E | BR3: =+BN3 -> 2022E
A4: Fiscal YE December | F4: 1Q | G4: 2Q | H4: 3Q | I4: 4Q | J4: Year | K4: 1Q | L4: 2Q | M4: 3Q | N4: 4Q | O4: Year | P4: 1Q | Q4: 2Q | R4: 3Q | S4: 4Q | T4: Year | U4: 1Q | V4: 2QE | W4: 3QE | X4: 4QE | Y4: Year | Z4: 1Q | AA4: 2Q | AB4: 3Q | AC4: 4Q | AD4: Year | AE4: 1Q | AF4: 2Q | AG4: 3Q | AH4: 4Q | AI4: Year | AJ4: 1Q | AK4: 2Q | AL4: 3Q | AM4: 4Q | AN4: Year | AO4: 1Q | AP4: 2Q | AQ4: 3Q | AR4: 4Q | AS4: Year | AT4: 1Q | AU4: 2Q | AV4: 3Q | AW4: 4Q | AX4: Year | AY4: 1Q | AZ4: 2Q | BA4: 3Q | BB4: 4QE | BC4: Year | BD4: 1QE | BE4: 2QE | BF4: 3QE | BG4: 4QE | BH4: Year | BI4: 1QE | BJ4: 2QE | BK4: 3QE | BL4: 4QE | BM4: Year | BN4: 1QE | BO4: 2QE | BP4: 3QE | BQ4: 4QE | BR4: Year
A5: ASSETS
A6: Current assets
B7: Cash and cash equivalents | F7: 256.927 | G7: 303.212 | H7: 213.077 | I7: =J7 -> 471.378 | J7: 471.378 | K7: 367.106 | L7: 420.978 | M7: 273.321 | N7: =O7 -> 204.24 | O7: 204.24 | P7: 190.414 | Q7: 185.386 | R7: 180.777 | S7: =T7 -> 168.056 | T7: 168.056 | U7: 132.318 | V7: 142.678 | W7: 127.902 | X7: =Y7 -> 119.923 | Y7: 119.923 | Z7: 133.064 | AA7: 139.858 | AB7: 137.228 | AC7: 135.583 | AD7: =AC7 -> 135.583 | AE7: 145.958 | AF7: 106.917 | AG7: 96.894 | AH7: 75.452 | AI7: =AH7 -> 75.452 | AJ7: 90.582 | AK7: 93.622 | AL7: 170.744 | AM7: 146.103 | AN7: =AM7 -> 146.103 | AO7: 104.817 | AP7: 172.927 | AQ7: 221.878 | AR7: 192.868 | AS7: =AR7 -> 192.868 | AT7: 174.34 | AU7: 138.569 | AV7: 118.258 | AW7: 116.075 | AX7: =AW7 -> 116.075 | AY7: 101.482 | AZ7: 149.881 | BA7: 207.13 | BB7: =CF!BB41 -> 362.24289 | BC7: =BB7 -> 362.24289 | BD7: =CF!BD41 -> 426.76477 | BE7: =CF!BE41 -> 527.27732 | BF7: =CF!BF41 -> 617.77956 | BG7: =CF!BG41 -> 683.3337 | BH7: =BG7 -> 683.3337 | BI7: =CF!BI41 -> 711.88308 | BJ7: =CF!BJ41 -> 741.59167 | BK7: =CF!BK41 -> 767.09412 | BL7: =CF!BL41 -> 801.43883 | BM7: =BL7 -> 801.43883 | BN7: =CF!BN41 -> 826.74709 | BO7: =CF!BO41 -> 852.74543 | BP7: =CF!BP41 -> 884.00147 | BQ7: =CF!BQ41 -> 919.54395 | BR7: =BQ7 -> 919.54395
B8: Restricted Cash | F8: 23.523 | G8: 23.523 | H8: 23.541 | I8: =J8 -> 23.55 | J8: 23.55 | K8: 28.008 | L8: 32.443 | M8: 35.817 | N8: =O8 -> 35.437 | O8: 35.437 | P8: 35.45 | Q8: 38.684 | R8: 38.7 | S8: =T8 -> 38.717 | T8: 38.717 | U8: 45.231 | V8: 47.019 | W8: 47.466 | X8: =Y8 -> 42.594 | Y8: 42.594 | Z8: 43.269 | AA8: 42.627 | AB8: 46.988 | AC8: 44.37 | AD8: =AC8 -> 44.37 | AE8: 44.093 | AF8: 39.493 | AG8: 38.572 | AH8: 45.853 | AI8: =AH8 -> 45.853 | AJ8: 49.158 | AK8: 49.452 | AL8: 48.725 | AM8: 50.504 | AN8: =AM8 -> 50.504 | AO8: 60.158 | AP8: 52.051 | AQ8: =17.424+48.775 -> 66.199 | AR8: =4.78+53.014 -> 57.794 | AS8: =AR8 -> 57.794 | AT8: 57.251 | AU8: 56.334 | AV8: 56.552 | AW8: 61.93 | AX8: =AW8 -> 61.93 | AY8: 69.032 | AZ8: =4.742+65.287 -> 70.029 | BA8: =6.261+67.728 -> 73.989 | BB8: =BA8 -> 73.989 | BC8: =BB8 -> 73.989 | BD8: =BB8 -> 73.989 | BE8: =BD8 -> 73.989 | BF8: =BE8 -> 73.989 | BG8: =BF8 -> 73.989 | BH8: =BG8 -> 73.989 | BI8: =BG8 -> 73.989 | BJ8: =BI8 -> 73.989 | BK8: =BJ8 -> 73.989 | BL8: =BK8 -> 73.989 | BM8: =BL8 -> 73.989 | BN8: =BL8 -> 73.989 | BO8: =BN8 -> 73.989 | BP8: =BO8 -> 73.989 | BQ8: =BP8 -> 73.989 | BR8: =BQ8 -> 73.989
B9: Accounts Receivable, including retainage | F9: 1115.997 | G9: 1193.315 | H9: 1121.657 | I9: =J9 -> 880.614 | J9: 880.614 | K9: 911.172 | L9: 1021.27 | M9: 1312.36 | N9: =O9 -> 1275.031 | O9: 1275.031 | P9: 1184.213 | Q9: 1198.764 | R9: 1249.787 | S9: =T9 -> 1224.613 | T9: 1224.613 | U9: 1331.555 | V9: 1389.511 | W9: 1397.857 | X9: =Y9 -> 1291.246 | Y9: 1291.246 | Z9: 1263.39 | AA9: 1454.045 | AB9: 1580.594 | AC9: 1479.504 | AD9: =AC9 -> 1479.504 | AE9: 1394.12 | AF9: 1553.514 | AG9: 1550.865 | AH9: 1473.615 | AI9: =AH9 -> 1473.615 | AJ9: 1615.661 | AK9: 1739.343 | AL9: 1718.685 | AM9: 1743.3 | AN9: =AM9 -> 1743.3 | AO9: 1749.602 | AP9: 1838.359 | AQ9: 1857.87 | AR9: 1801.656 | AS9: =AR9 -> 1801.656 | AT9: 1767.715 | AU9: 1763.683 | AV9: 1818.402 | AW9: =1261.072+478.744 -> 1739.816 | AX9: =AW9 -> 1739.816 | AY9: 1838.013 | AZ9: =1469.213+508.423 -> 1977.636 | BA9: =1460.45+542.274 -> 2002.724 | BB9: =BB60*BB$50 -> 2082.7703 | BC9: =BB9 -> 2082.7703 | BD9: =BD60*BD$50 -> 2154.0312 | BE9: =BE60*BE$50 -> 2326.656 | BF9: =BF60*BF$50 -> 2481.4606 | BG9: =BG60*BG$50 -> 2576.8689 | BH9: =BG9 -> 2576.8689 | BI9: =BI60*BI$50 -> 2560.6315 | BJ9: =BJ60*BJ$50 -> 2562.2943 | BK9: =BK60*BK$50 -> 2554.1844 | BL9: =BL60*BL$50 -> 2565.3368 | BM9: =BL9 -> 2565.3368 | BN9: =BN60*BN$50 -> 2542.2388 | BO9: =BO60*BO$50 -> 2534.9964 | BP9: =BP60*BP$50 -> 2540.4567 | BQ9: =BQ60*BQ$50 -> 2553.8048 | BR9: =BQ9 -> 2553.8048
B10: Costs and Estimated Earnings in Excess of Billings | F10: 134.825 | G10: 120.28 | H10: 123.497 | I10: =J10 -> 139.449 | J10: 139.449 | K10: 172.54 | L10: 215.117 | M10: 374.325 | N10: =O10 -> 358.398 | O10: 358.398 | P10: 377.599 | Q10: 374.936 | R10: 411.662 | S10: =T10 -> 465.002 | T10: 465.002 | U10: 479.361 | V10: 504.911 | W10: 538.421 | X10: =Y10 -> 573.248 | Y10: 573.248 | Z10: 698.423 | AA10: 660.952 | AB10: 720.177 | AC10: 726.402 | AD10: =AC10 -> 726.402 | AE10: 795.51 | AF10: 816.48 | AG10: 883.809 | AH10: 905.175 | AI10: =AH10 -> 905.175 | AJ10: 858.356 | AK10: 811.406 | AL10: 820.243 | AM10: 831.826 | AN10: =AM10 -> 831.826 | AO10: 840.76 | AP10: 850.634 | AQ10: 902.312 | AR10: 932.758 | AS10: =AR10 -> 932.758 | AT10: 980.896 | AU10: 1044.233 | AV10: 1085.651 | AW10: 1142.295 | AX10: =AW10 -> 1142.295 | AY10: 1168.675 | AZ10: 1165.408 | BA10: 1159.333 | BB10: =BB61*BB$50 -> 556.76031 | BC10: =BB10 -> 556.76031 | BD10: =BD61*BD$50 -> 576.45163 | BE10: =BE61*BE$50 -> 623.34373 | BF10: =BF61*BF$50 -> 665.56103 | BG10: =BG61*BG$50 -> 691.92408 | BH10: =BG10 -> 691.92408 | BI10: =BI61*BI$50 -> 688.33424 | BJ10: =BJ61*BJ$50 -> 689.55355 | BK10: =BK61*BK$50 -> 688.14267 | BL10: =BL61*BL$50 -> 691.92408 | BM10: =BL10 -> 691.92408 | BN10: =BN61*BN$50 -> 686.46554 | BO10: =BO61*BO$50 -> 685.28093 | BP10: =BP61*BP$50 -> 687.53141 | BQ10: =BQ61*BQ$50 -> 691.92408 | BR10: =BQ10 -> 691.92408
B11: Deferred Income taxes | F11: 1.393 | G11: 1.369 | H11: 1.41 | I11: =J11 -> 3.737 | J11: 3.737 | K11: 3.782 | L11: 11.44 | M11: 18.559 | N11: =O11 -> 0 | O11: 0 | P11: 1.958 | Q11: 2.931 | R11: 3.246 | S11: =T11 -> 10.071 | T11: 10.071 | U11: 9.721 | V11: 9.452 | W11: 9.631 | X11: =Y11 -> 8.24 | Y11: 8.24 | Z11: 8.195 | AA11: 7.982 | AB11: 7.951 | AC11: 17.962 | AD11: =AC11 -> 17.962 | AE11: 17.962 | AF11: 17.952 | AG11: 18.873 | AH11: 26.306 | AI11: =AH11 -> 26.306 | AJ11: 26.55 | AK11: 19.098 | AL11: 26.029 | AM11: 0 | AN11: =AM11 -> 0 | AO11: 0 | AP11: 0 | AQ11: 0 | AS11: =AR11 -> 0
B12: Other Current Assets | F12: 33.527 | G12: 37.345 | H12: 44.867 | I12: =J12 -> 42.314 | J12: 42.314 | K12: 35.372 | L12: 52.86 | M12: 93.767 | N12: =O12 -> 76.928 | O12: 76.928 | P12: 87.862 | Q12: 101.684 | R12: 76.021 | S12: =T12 -> 75.388 | T12: 75.388 | U12: 74.5 | V12: 53.814 | W12: 48.36 | X12: =Y12 -> 50.669 | Y12: 50.669 | Z12: 54.858 | AA12: 52.42 | AB12: 69.318 | AC12: 68.735 | AD12: =AC12 -> 68.735 | AE12: 74.367 | AF12: 103.243 | AG12: 86.734 | AH12: 108.844 | AI12: =AH12 -> 108.844 | AJ12: 91.99 | AK12: 76.96 | AL12: 65.511 | AM12: 66.023 | AN12: =AM12 -> 66.023 | AO12: 58.482 | AP12: 77.736 | AQ12: 70.781 | AR12: 89.316 | AS12: =AR12 -> 89.316 | AT12: 132.298 | AU12: 141.472 | AV12: 130.023 | AW12: 115.527 | AX12: =AW12 -> 115.527 | AY12: 124.303 | AZ12: 165.688 | BA12: 162.406 | BB12: =BB63*BB$50 -> 73.264895 | BC12: =BB12 -> 73.264895 | BD12: =BD63*BD$50 -> 75.856103 | BE12: =BE63*BE$50 -> 82.026703 | BF12: =BF63*BF$50 -> 87.582139 | BG12: =BG63*BG$50 -> 91.051291 | BH12: =BG12 -> 91.051291 | BI12: =BI63*BI$50 -> 90.578899 | BJ12: =BJ63*BJ$50 -> 90.739349 | BK12: =BK63*BK$50 -> 90.55369 | BL12: =BL63*BL$50 -> 91.051291 | BM12: =BL12 -> 91.051291 | BN12: =BN63*BN$50 -> 90.332993 | BO12: =BO63*BO$50 -> 90.177109 | BP12: =BP63*BP$50 -> 90.473253 | BQ12: =BQ63*BQ$50 -> 91.051291 | BR12: =BQ12 -> 91.051291
D13: Total Current Assets | F13: =SUM(F7:F12) -> 1566.192 | G13: =SUM(G7:G12) -> 1679.044 | H13: =SUM(H7:H12) -> 1528.049 | I13: =SUM(I7:I12) -> 1561.042 | J13: =SUM(J7:J12) -> 1561.042 | K13: =SUM(K7:K12) -> 1517.98 | L13: =SUM(L7:L12) -> 1754.108 | M13: =SUM(M7:M12) -> 2108.149 | ... BR13: =SUM(BR7:BR12) -> 4330.3131
A14: Long-term assets
B15: Long-term Investments | F15: 100.826 | G15: 100.316 | H15: 94.023 | I15: =J15 -> 88.129 | J15: 88.129 | K15: 88.129 | L15: 88.129 | M15: 67.061 | N15: =O15 -> 62.311 | O15: 62.311 | P15: 46.283 | Q15: 46.283 | R15: 46.283 | S15: =T15 -> 46.283 | T15: 46.283 | U15: 46.283 | V15: 46.283 | W15: 46.283 | X15: =Y15 -> 46.283 | Y15: 46.283 | Z15: 46.283 | AA15: 0 | AB15: 0 | AC15: 0 | AD15: =AC15 -> 0 | AE15: 0 | AF15: 0 | AG15: 0 | AH15: 0 | AI15: =AH15 -> 0
C16: Accumulated depreciation | I16: =J16 -> 0 | N16: =O16 -> 0 | S16: =T16 -> 0 | X16: =Y16 -> 0 | AD16: =AC16 -> 0 | AI16: =AH16 -> 0 | AN16: =AM16 -> 0 | AS16: =AR16 -> 0 | AX16: =AW16 -> 0 | BC16: =BB16 -> 0 | BH16: =BG16 -> 0 | BM16: =BL16 -> 0 | BR16: =BQ16 -> 0
C17: Property, plant and equipment, gross | I17: =J17 -> 0 | N17: =O17 -> 0 | S17: =T17 -> 0 | X17: =Y17 -> 0 | AD17: =AC17 -> 0 | AI17: =AH17 -> 0 | AN17: =AM17 -> 0 | AS17: =AR17 -> 0 | AX17: =AW17 -> 0 | BC17: =BB17 -> 0 | BH17: =BG17 -> 0 | BM17: =BL17 -> 0 | BR17: =BQ17 -> 0
B18: Property, Plant and Equipment (less Accumulated Depreciation) | F18: 351.398 | G18: 353.506 | H18: 354.995 | I18: =J18 -> 362.437 | J18: 362.437 | K18: 373.45 | L18: 424.869 | M18: 472.528 | N18: =O18 -> 491.377 | O18: 491.377 | P18: 490.011 | Q18: 488.491 | R18: 488.114 | S18: =T18 -> 485.095 | T18: 485.095 | U18: 487.385 | V18: 491.457 | W18: 493.326 | X18: =Y18 -> 498.125 | Y18: 498.125 | Z18: 516.683 | AA18: 529.545 | AB18: 526.981 | AC18: 527.602 | AD18: =AC18 -> 527.602 | AE18: 523.622 | AF18: 537.833 | AG18: 531.438 | AH18: 523.525 | AI18: =AH18 -> 523.525 | AJ18: 519.89 | AK18: 507.395 | AL18: 492.328 | AM18: 477.626 | AN18: =AM18 -> 477.626 | AO18: 462.695 | AP18: 456.001 | AQ18: 447.588 | AR18: 467.499 | AS18: =AR18 -> 467.499 | AT18: 473.178 | AU18: 490.614 | AV18: 494.498 | AW18: 490.669 | AX18: =AW18 -> 490.669 | AY18: 492.929 | AZ18: 502.675 | BA18: 509.986 | BB18: =BA18-CF!BL22-CF!BL8 -> 499.986 | BC18: =BB18 -> 499.986 | BD18: =BC18-CF!BN22-CF!BN8 -> 489.986 | BE18: =BD18-CF!BO22-CF!BO8 -> 479.986 | BF18: =BE18-CF!BP22-CF!BP8 -> 469.986 | BG18: =BF18-CF!BQ22-CF!BQ8 -> 459.986 | BH18: =BG18 -> 459.986 | BI18: =BH18-CF!BS22-CF!BS8 -> 459.986 | BJ18: =BI18-CF!BT22-CF!BT8 -> 459.986 | BK18: =BJ18-CF!BU22-CF!BU8 -> 459.986 | BL18: =BK18-CF!BV22-CF!BV8 -> 459.986 | BM18: =BL18 -> 459.986 | BN18: =BM18-CF!BX22-CF!BX8 -> 459.986 | BO18: =BN18-CF!BY22-CF!BY8 -> 459.986 | BP18: =BO18-CF!BZ22-CF!BZ8 -> 459.986 | BQ18: =BP18-CF!CA22-CF!CA8 -> 459.986 | BR18: =BQ18 -> 459.986
B19: Goodwill | F19: 602.471 | G19: 602.471 | H19: 602.471 | I19: =J19 -> 621.92 | J19: 621.92 | K19: 651.429 | L19: 691.077 | M19: 881.538 | N19: =O19 -> 892.602 | O19: 892.602 | P19: 893.79 | Q19: 570.646 | R19: 570.646 | S19: =T19 -> 570.646 | T19: 570.646 | U19: 570.646 | V19: 570.646 | W19: 571.932 | X19: =Y19 -> 577.756 | Y19: 577.756 | Z19: 577.756 | AA19: 585.006 | AB19: 585.006 | AC19: 585.006 | AD19: =AC19 -> 585.006 | AE19: 585.006 | AF19: 585.006 | AG19: 585.006 | AH19: 585.006 | AI19: =AH19 -> 585.006 | AJ19: 585.006 | AK19: 585.006 | AL19: 585.006 | AM19: 585.006 | AN19: =AM19 -> 585.006 | AO19: 585.006 | AP19: 585.006 | AQ19: 585.006 | AR19: 585.006 | AS19: =AR19 -> 585.006 | AT19: 585.006 | AU19: 585.006 | AV19: 585.006 | AW19: 585.006 | AX19: =AW19 -> 585.006 | AY19: 585.006 | AZ19: 205.143 | BA19: 205.143 | BB19: =BA19 -> 205.143 | BC19: =BB19 -> 205.143 | BD19: =BB19 -> 205.143 | BE19: =BD19 -> 205.143 | BF19: =BE19 -> 205.143 | BG19: =BF19 -> 205.143 | BH19: =BG19 -> 205.143 | BI19: =BG19 -> 205.143 | BJ19: =BI19 -> 205.143 | BK19: =BJ19 -> 205.143 | BL19: =BK19 -> 205.143 | BM19: =BL19 -> 205.143 | BN19: =BL19 -> 205.143 | BO19: =BN19 -> 205.143 | BP19: =BO19 -> 205.143 | BQ19: =BP19 -> 205.143 | BR19: =BQ19 -> 205.143
B20: Intangible Assets, net | F20: 132.089 | G20: 130.051 | H20: 128.105 | I20: =J20 -> 132.551 | J20: 132.551 | K20: 151.081 | L20: 160.206 | M20: 203.075 | N20: =O20 -> 197.999 | O20: 197.999 | P20: 192.96 | Q20: 133.715 | R20: 130.092 | S20: =T20 -> 126.821 | T20: 126.821 | U20: 123.551 | V20: 120.281 | W20: 117.01 | X20: =Y20 -> 113.74 | Y20: 113.74 | Z20: 110.071 | AA20: 106.403 | AB20: 103.329 | AC20: 100.254 | AD20: =AC20 -> 100.254 | AE20: 99.311 | AF20: 98.368 | AG20: 97.425 | AH20: 96.54 | AI20: =AH20 -> 96.54 | AJ20: 95.654 | AK20: 94.768 | AL20: 93.883 | AM20: 92.997 | AN20: =AM20 -> 92.997 | AO20: 92.111 | AP20: 91.226 | AQ20: 90.34 | AR20: 89.454 | AS20: =AR20 -> 89.454 | AT20: 88.568 | AU20: 87.683 | AV20: 86.797 | AW20: 85.911 | AX20: =AW20 -> 85.911 | AY20: 85.026 | AZ20: 84.14 | BA20: 83.254 | BB20: =BA20 -> 83.254 | BC20: =BB20 -> 83.254 | BD20: =BB20 -> 83.254 | BE20: =BD20 -> 83.254 | BF20: =BE20 -> 83.254 | BG20: =BF20 -> 83.254 | BH20: =BG20 -> 83.254 | BI20: =BG20 -> 83.254 | BJ20: =BI20 -> 83.254 | BK20: =BJ20 -> 83.254 | BL20: =BK20 -> 83.254 | BM20: =BL20 -> 83.254 | BN20: =BL20 -> 83.254 | BO20: =BN20 -> 83.254 | BP20: =BO20 -> 83.254 | BQ20: =BP20 -> 83.254 | BR20: =BQ20 -> 83.254
